Workbook
Name 输入方式: #REF!

Sheet 待定问题列表
A1: Amarsoft Technology Co., Ltd.
A2: 待定问题跟踪列表
B3: 编号 | C3: 问题分类 | D3: 问题描述 | E3: 问题提出时间 | F3: 跟踪人 | G3: 解决状态 | H3: 解决时间 | I3: 解决方案 | J3: 解决人
B4: 1 | C4: 数据标准要求 | D4: 目前对于质押品类型为同业存单的数据项标准缺失，因此需要贝老师与金融市场部相关同事商议给出同业存单的数据标准 | E4: 41921 | F4: 贝隽希、蒋敏 | G4: 已解决 | H4: 41935 | I4: 已提供 | J4: 贝隽希
B5: 2 | C5: 数据采集要求 | D5: 目前在房地产成本法估值计算时需要用到建筑物剩余使用年限，对于实际的业务操作过程中，国家法律法规对于建筑物剩余使用年限的计算方法以及管理约定是如何定义的，需要蒋老师确定 | E5: 41923 | F5: 蒋敏 | G5: 已解决 | H5: 41925 | I5: 1、土地使用权年限的标准：根据我国《城镇国有土地使用权出让和转让暂行条例》第12条规定，土地使用权出让最高年限按下列用途确定：A).居住用地70年;B).工业用地50年;C).教育、科技、文化、卫生、体育用地年限为50年;D).商业、旅游、娱乐用地40年;E).仓储用地50年;F).综合或者其他用地50年。 2、土地使用权年限的计算：按照开始缴纳土地出让金的时间开始算起，从开发商取得《国有土地许可证》的时间来核定其土地使用年限。 3、土地剩余使用年限的计算：在房产证上一般都会有写明一个使用截止日。如果没写，看房产证上的批地时间是什么时候，然后再加上70年，就是房屋土地的使用到期日，再减去使用过的时间，就是剩下的期限了。 4、二手房的土地剩余使用年限的计算：举个例子说明： (1)如已购公房和央产房的土地是以划拨方式取得的，即从该楼的第一套房屋首次进入二手房市场，缴纳土地出让金之日起核定其土地出让年限。其他房屋上市时，依上述办法分别计算使用年限，最终保证同一宗土地、同一栋楼的土地出让年限终止日相同。 例如：某栋钢混结构房屋1998年竣工，该楼第一套房屋首次进入二手房市场的交易日期为2000年，因此该栋楼的整体土地使用年限也从2000年开始算起，即最终土地使用年限截止日期为2070年。2003年业主将这套房屋出售，那么购房者购买后的土地使用年限为70年-(2003年-2000年)=67年。也就是说，新业主即将有67年的土地使用时间，该套房屋的新购买时间2003年+67年=2070年。同一宗土地、同一栋楼的土地出让年限终止日相同。 (2)如已购公有住房新占土地是以出让方式取得的，其70年的土地使用年限以原签署的《国有土地使用权出让合同》或《转让合同》，以及下发的《国有土地使用证》核定土地使用年限为准。(一般是从竣工日期算起) 例如：某砖混结构的房屋1997年竣工，它的《国有土地使用证》下发时间为2000年，而该房屋所下发的《国有土地使用证》上标注的使用年限为“1997年至2067年”，也就是说该房屋的土地使用年限从1997年开始算起。那么，如果这套房屋的业主于2004年出售该房产，其新的土地使用年限=70年-(2004年-1997年)=63年。该套房屋的新购买时间2004年+交易后核定的土地年限年63年=2067年，即这套房屋的最终土地使用年限到2067年为止。 | J5: 蒋敏
B6: 3 | C6: 数据标准要求 | D6: 对于抵质押品类型为金融质押品-存单或存款的分类定义：目前风险政策部的纪老师确定将我行存款类押品放入至其他质押品类别下，个人认为这样不合理，需要与纪老师重新商定！ | E6: 41923 | F6: 贝隽希、蒋敏 | G6: 未解决
B7: 4 | C7: 数据标准要求 | D7: 对于抵质押品的公共数据项中，抵质押品合格性数据的数据标准定义需要明确，合格性认定每年做一次，如果在押品系统上线后，其合格性认定的算法取值如何处理？ | E7: 41925 | F7: 贝隽希、蒋敏 | G7: 解决中
B8: 5 | C8: 数据标准要求 | D8: 对于金融市场业务中可交易的债券，是否与企业信贷服务系统中的债券信息加以区分？对于债券、股票、基金等押品，其唯一性识别要素该如何定义？是否就无核心识别要素，仅存在疑似就可以？实际业务上，是否已控制债券以及股票的总量？ | E8: 41930 | F8: 贝隽希、蒋敏 | G8: 未解决
B9: 6 | C9: 数据管理要求 | D9: 对于抵质押品类型为我行出售的贵金属和金交所托管的贵金属两种类型，唯一性识别要素是如何确定的，需要业务部门进一步明确 | E9: 41934 | F9: 业务专家 | G9: 未解决
B10: 7 | C10: 数据管理要求 | D10: 对于抵质押品类型为应收账款-交易类应收账款、收费权类应收账款、其他类应收账款等，在实际的业务操作过程中是如何定义押品的？以公路收费权为例，除收费权登记号、收费期间之外，对于收费路段范围的定义如何？ | E10: 41934 | F10: 陆蔚峰 | G10: 未解决
B11: 8 | C11: 数据标准要求 | D11: 对于抵质押品类型为其他押品-货权类中包括仓单和提单两种类型，但是抵质押品数据项中，仅针对仓单的数据项，未体现提单的数据项定义。 | E11: 41934 | F11: 业务专家 | G11: 未解决
B12: 9 | C12: 数据管理要求 | D12: 对于抵质押品类型为其他押品-实物存货，唯一性识别要素是如何确定的，需要业务部门进一步明确 | E12: 41934 | F12: 业务专家 | G12: 未解决
B13: 10 | C13: 数据管理要求 | D13: 目前对于抵质押品类型为其他押品-交通运输设备-船舶、在建船舶以及航空器、在建航空器的唯一性识别要素是如何定义的？ | E13: 41934 | F13: 业务专家 | G13: 未解决
B14: 11 | C14: 数据标准要求 | D14: 对于抵质押品类型为其他押品-出口退税账户，需业务部门明确出口退税账户的数据项定义是否满足实际业务要求？ | E14: 41934 | F14: 业务专家 | G14: 未解决
B15: 12 | C15: 数据管理要求 | D15: 对于抵质押品类型为其他押品-资源资产-采矿权、森林和林木使用权、林地使用权、海域使用权、荒地土地承包经营权等，在实际的业务操作过程中是如何定义押品的？唯一性识别要素当如何定义？ | E15: 41934 | F15: 业务专家 | G15: 未解决

Sheet 原型
A1: 系统四级分类 | B1: 系统四级分类 | C1: 系统四级分类 | D1: 系统四级分类 | E1: =CLEAN(A1)&"|"&CLEAN(B1)&"|"&CLEAN(C1)&"|"&CLEAN(D1) -> 系统四级分类|系统四级分类|系统四级分类|系统四级分类 | F1: =CLEAN(B1)&"|"&CLEAN(C1)&"|"&CLEAN(D1) -> 系统四级分类|系统四级分类|系统四级分类 | G1: =CLEAN(C1)&"|"&CLEAN(D1) -> 系统四级分类|系统四级分类 | H1: 全匹配 | I1: 匹配234 | J1: 匹配34 | K1: 匹配1 | L1: 匹配2 | M1: 匹配3 | N1: 匹配4 | O1: 系统四级分类 | P1: 系统四级分类 | Q1: 系统四级分类 | R1: 系统四级分类
A2: 一级分类 | B2: 二级分类 | C2: 三级分类 | D2: 四级分类 | E2: =CLEAN(A2)&"|"&CLEAN(B2)&"|"&CLEAN(C2)&"|"&CLEAN(D2) -> 一级分类|二级分类|三级分类|四级分类 | F2: =CLEAN(B2)&"|"&CLEAN(C2)&"|"&CLEAN(D2) -> 二级分类|三级分类|四级分类 | G2: =CLEAN(C2)&"|"&CLEAN(D2) -> 三级分类|四级分类 | H2: =IF(ISERROR(VLOOKUP(E2,新系统!E:E,1,0)),"原型有新系统没有","") -> 原型有新系统没有 | I2: =IF(ISERROR(VLOOKUP(F2,新系统!F:F,1,0)),"原型有新系统没有","") -> 原型有新系统没有 | J2: =IF(ISERROR(VLOOKUP(G2,新系统!G:G,1,0)),"原型有新系统没有","") -> 原型有新系统没有 | K2: =IF(ISERROR(VLOOKUP(O2,新系统!O:O,1,0)),"原型有新系统没有","") -> 原型有新系统没有 | L2: =IF(ISERROR(VLOOKUP(P2,新系统!P:P,1,0)),"原型有新系统没有","") -> 原型有新系统没有 | M2: =IF(ISERROR(VLOOKUP(Q2,新系统!Q:Q,1,0)),"原型有新系统没有","") -> 原型有新系统没有 | N2: =IF(ISERROR(VLOOKUP(R2,新系统!R:R,1,0)),"原型有新系统没有","") -> 原型有新系统没有 | O2: 一级分类 | P2: 二级分类 | Q2: 三级分类 | R2: 四级分类
A3: 金融质押品 | B3: 现金及其等价物 | C3: 存单或存款 | D3: 我行存单 | E3: =CLEAN(A3)&"|"&CLEAN(B3)&"|"&CLEAN(C3)&"|"&CLEAN(D3) -> 金融质押品|现金及其等价物|存单或存款|我行存单 | F3: =CLEAN(B3)&"|"&CLEAN(C3)&"|"&CLEAN(D3) -> 现金及其等价物|存单或存款|我行存单 | G3: =CLEAN(C3)&"|"&CLEAN(D3) -> 存单或存款|我行存单 | H3: =IF(ISERROR(VLOOKUP(E3,新系统!E:E,1,0)),"原型有新系统没有","") | I3: =IF(ISERROR(VLOOKUP(F3,新系统!F:F,1,0)),"原型有新系统没有","") | J3: =IF(ISERROR(VLOOKUP(G3,新系统!G:G,1,0)),"原型有新系统没有","") | K3: =IF(ISERROR(VLOOKUP(O3,新系统!O:O,1,0)),"原型有新系统没有","") | L3: =IF(ISERROR(VLOOKUP(P3,新系统!P:P,1,0)),"原型有新系统没有","") | M3: =IF(ISERROR(VLOOKUP(Q3,新系统!Q:Q,1,0)),"原型有新系统没有","") | N3: =IF(ISERROR(VLOOKUP(R3,新系统!R:R,1,0)),"原型有新系统没有","") | O3: 金融质押品 | P3: 现金及其等价物 | Q3: 存单或存款 | R3: 我行存单
A4: 金融质押品 | B4: 现金及其等价物 | C4: 存单或存款 | D4: 他行存单 | E4: =CLEAN(A4)&"|"&CLEAN(B4)&"|"&CLEAN(C4)&"|"&CLEAN(D4) -> 金融质押品|现金及其等价物|存单或存款|他行存单 | F4: =CLEAN(B4)&"|"&CLEAN(C4)&"|"&CLEAN(D4) -> 现金及其等价物|存单或存款|他行存单 | G4: =CLEAN(C4)&"|"&CLEAN(D4) -> 存单或存款|他行存单 | H4: =IF(ISERROR(VLOOKUP(E4,新系统!E:E,1,0)),"原型有新系统没有","") | I4: =IF(ISERROR(VLOOKUP(F4,新系统!F:F,1,0)),"原型有新系统没有","") | J4: =IF(ISERROR(VLOOKUP(G4,新系统!G:G,1,0)),"原型有新系统没有","") | K4: =IF(ISERROR(VLOOKUP(O4,新系统!O:O,1,0)),"原型有新系统没有","") | L4: =IF(ISERROR(VLOOKUP(P4,新系统!P:P,1,0)),"原型有新系统没有","") | M4: =IF(ISERROR(VLOOKUP(Q4,新系统!Q:Q,1,0)),"原型有新系统没有","") | N4: =IF(ISERROR(VLOOKUP(R4,新系统!R:R,1,0)),"原型有新系统没有","") | O4: 金融质押品 | P4: 现金及其等价物 | Q4: 存单或存款 | R4: 他行存单
A5: 金融质押品 | B5: 现金及其等价物 | C5: 保证金 | D5: 保证金 | E5: =CLEAN(A5)&"|"&CLEAN(B5)&"|"&CLEAN(C5)&"|"&CLEAN(D5) -> 金融质押品|现金及其等价物|保证金|保证金 | F5: =CLEAN(B5)&"|"&CLEAN(C5)&"|"&CLEAN(D5) -> 现金及其等价物|保证金|保证金 | G5: =CLEAN(C5)&"|"&CLEAN(D5) -> 保证金|保证金 | H5: =IF(ISERROR(VLOOKUP(E5,新系统!E:E,1,0)),"原型有新系统没有","") | I5: =IF(ISERROR(VLOOKUP(F5,新系统!F:F,1,0)),"原型有新系统没有","") | J5: =IF(ISERROR(VLOOKUP(G5,新系统!G:G,1,0)),"原型有新系统没有","") | K5: =IF(ISERROR(VLOOKUP(O5,新系统!O:O,1,0)),"原型有新系统没有","") | L5: =IF(ISERROR(VLOOKUP(P5,新系统!P:P,1,0)),"原型有新系统没有","") | M5: =IF(ISERROR(VLOOKUP(Q5,新系统!Q:Q,1,0)),"原型有新系统没有","") | N5: =IF(ISERROR(VLOOKUP(R5,新系统!R:R,1,0)),"原型有新系统没有","") | O5: 金融质押品 | P5: 现金及其等价物 | Q5: 保证金 | R5: 保证金
A6: 金融质押品 | B6: 贵金属 | C6: 我行出售的贵金属 | D6: 我行出售的贵金属 | E6: =CLEAN(A6)&"|"&CLEAN(B6)&"|"&CLEAN(C6)&"|"&CLEAN(D6) -> 金融质押品|贵金属|我行出售的贵金属|我行出售的贵金属 | F6: =CLEAN(B6)&"|"&CLEAN(C6)&"|"&CLEAN(D6) -> 贵金属|我行出售的贵金属|我行出售的贵金属 | G6: =CLEAN(C6)&"|"&CLEAN(D6) -> 我行出售的贵金属|我行出售的贵金属 | H6: =IF(ISERROR(VLOOKUP(E6,新系统!E:E,1,0)),"原型有新系统没有","") | I6: =IF(ISERROR(VLOOKUP(F6,新系统!F:F,1,0)),"原型有新系统没有","") | J6: =IF(ISERROR(VLOOKUP(G6,新系统!G:G,1,0)),"原型有新系统没有","") | K6: =IF(ISERROR(VLOOKUP(O6,新系统!O:O,1,0)),"原型有新系统没有","") | L6: =IF(ISERROR(VLOOKUP(P6,新系统!P:P,1,0)),"原型有新系统没有","") | M6: =IF(ISERROR(VLOOKUP(Q6,新系统!Q:Q,1,0)),"原型有新系统没有","") | N6: =IF(ISERROR(VLOOKUP(R6,新系统!R:R,1,0)),"原型有新系统没有","") | O6: 金融质押品 | P6: 贵金属 | Q6: 我行出售的贵金属 | R6: 我行出售的贵金属
A7: 金融质押品 | B7: 贵金属 | C7: 金交所托管的贵金属 | D7: 黄金 | E7: =CLEAN(A7)&"|"&CLEAN(B7)&"|"&CLEAN(C7)&"|"&CLEAN(D7) -> 金融质押品|贵金属|金交所托管的贵金属|黄金 | F7: =CLEAN(B7)&"|"&CLEAN(C7)&"|"&CLEAN(D7) -> 贵金属|金交所托管的贵金属|黄金 | G7: =CLEAN(C7)&"|"&CLEAN(D7) -> 金交所托管的贵金属|黄金 | H7: =IF(ISERROR(VLOOKUP(E7,新系统!E:E,1,0)),"原型有新系统没有","") | I7: =IF(ISERROR(VLOOKUP(F7,新系统!F:F,1,0)),"原型有新系统没有","") | J7: =IF(ISERROR(VLOOKUP(G7,新系统!G:G,1,0)),"原型有新系统没有","") | K7: =IF(ISERROR(VLOOKUP(O7,新系统!O:O,1,0)),"原型有新系统没有","") | L7: =IF(ISERROR(VLOOKUP(P7,新系统!P:P,1,0)),"原型有新系统没有","") | M7: =IF(ISERROR(VLOOKUP(Q7,新系统!Q:Q,1,0)),"原型有新系统没有","") | N7: =IF(ISERROR(VLOOKUP(R7,新系统!R:R,1,0)),"原型有新系统没有","") | O7: 金融质押品 | P7: 贵金属 | Q7: 金交所托管的贵金属 | R7: 黄金
A8: 金融质押品 | B8: 贵金属 | C8: 金交所托管的贵金属 | D8: 标准银、铂金等其他贵金属 | E8: =CLEAN(A8)&"|"&CLEAN(B8)&"|"&CLEAN(C8)&"|"&CLEAN(D8) -> 金融质押品|贵金属|金交所托管的贵金属|标准银、铂金等其他贵金属 | F8: =CLEAN(B8)&"|"&CLEAN(C8)&"|"&CLEAN(D8) -> 贵金属|金交所托管的贵金属|标准银、铂金等其他贵金属 | G8: =CLEAN(C8)&"|"&CLEAN(D8) -> 金交所托管的贵金属|标准银、铂金等其他贵金属 | H8: =IF(ISERROR(VLOOKUP(E8,新系统!E:E,1,0)),"原型有新系统没有","") | I8: =IF(ISERROR(VLOOKUP(F8,新系统!F:F,1,0)),"原型有新系统没有","") | J8: =IF(ISERROR(VLOOKUP(G8,新系统!G:G,1,0)),"原型有新系统没有","") | K8: =IF(ISERROR(VLOOKUP(O8,新系统!O:O,1,0)),"原型有新系统没有","") | L8: =IF(ISERROR(VLOOKUP(P8,新系统!P:P,1,0)),"原型有新系统没有","") | M8: =IF(ISERROR(VLOOKUP(Q8,新系统!Q:Q,1,0)),"原型有新系统没有","") | N8: =IF(ISERROR(VLOOKUP(R8,新系统!R:R,1,0)),"原型有新系统没有","") | O8: 金融质押品 | P8: 贵金属 | Q8: 金交所托管的贵金属 | R8: 标准银铂金等其他贵金属
A9: 金融质押品 | B9: 同业存单 | C9: 同业存单 | D9: 同业存单 | E9: =CLEAN(A9)&"|"&CLEAN(B9)&"|"&CLEAN(C9)&"|"&CLEAN(D9) -> 金融质押品|同业存单|同业存单|同业存单 | F9: =CLEAN(B9)&"|"&CLEAN(C9)&"|"&CLEAN(D9) -> 同业存单|同业存单|同业存单 | G9: =CLEAN(C9)&"|"&CLEAN(D9) -> 同业存单|同业存单 | H9: =IF(ISERROR(VLOOKUP(E9,新系统!E:E,1,0)),"原型有新系统没有","") | I9: =IF(ISERROR(VLOOKUP(F9,新系统!F:F,1,0)),"原型有新系统没有","") | J9: =IF(ISERROR(VLOOKUP(G9,新系统!G:G,1,0)),"原型有新系统没有","") | K9: =IF(ISERROR(VLOOKUP(O9,新系统!O:O,1,0)),"原型有新系统没有","") | L9: =IF(ISERROR(VLOOKUP(P9,新系统!P:P,1,0)),"原型有新系统没有","") | M9: =IF(ISERROR(VLOOKUP(Q9,新系统!Q:Q,1,0)),"原型有新系统没有","") | N9: =IF(ISERROR(VLOOKUP(R9,新系统!R:R,1,0)),"原型有新系统没有","") | O9: 金融质押品 | P9: 同业存单 | Q9: 同业存单 | R9: 同业存单
A10: 金融质押品 | B10: 债券 | C10: 国债 | D10: 储蓄国债 | E10: =CLEAN(A10)&"|"&CLEAN(B10)&"|"&CLEAN(C10)&"|"&CLEAN(D10) -> 金融质押品|债券|国债|储蓄国债 | F10: =CLEAN(B10)&"|"&CLEAN(C10)&"|"&CLEAN(D10) -> 债券|国债|储蓄国债 | G10: =CLEAN(C10)&"|"&CLEAN(D10) -> 国债|储蓄国债 | H10: =IF(ISERROR(VLOOKUP(E10,新系统!E:E,1,0)),"原型有新系统没有","") | I10: =IF(ISERROR(VLOOKUP(F10,新系统!F:F,1,0)),"原型有新系统没有","") | J10: =IF(ISERROR(VLOOKUP(G10,新系统!G:G,1,0)),"原型有新系统没有","") | K10: =IF(ISERROR(VLOOKUP(O10,新系统!O:O,1,0)),"原型有新系统没有","") | L10: =IF(ISERROR(VLOOKUP(P10,新系统!P:P,1,0)),"原型有新系统没有","") | M10: =IF(ISERROR(VLOOKUP(Q10,新系统!Q:Q,1,0)),"原型有新系统没有","") | N10: =IF(ISERROR(VLOOKUP(R10,新系统!R:R,1,0)),"原型有新系统没有","") | O10: 金融质押品 | P10: 债券 | Q10: 国债 | R10: 储蓄国债
A11: 金融质押品 | B11: 债券 | C11: 国债 | D11: 凭证国债 | E11: =CLEAN(A11)&"|"&CLEAN(B11)&"|"&CLEAN(C11)&"|"&CLEAN(D11) -> 金融质押品|债券|国债|凭证国债 | F11: =CLEAN(B11)&"|"&CLEAN(C11)&"|"&CLEAN(D11) -> 债券|国债|凭证国债 | G11: =CLEAN(C11)&"|"&CLEAN(D11) -> 国债|凭证国债 | H11: =IF(ISERROR(VLOOKUP(E11,新系统!E:E,1,0)),"原型有新系统没有","") | I11: =IF(ISERROR(VLOOKUP(F11,新系统!F:F,1,0)),"原型有新系统没有","") | J11: =IF(ISERROR(VLOOKUP(G11,新系统!G:G,1,0)),"原型有新系统没有","") | K11: =IF(ISERROR(VLOOKUP(O11,新系统!O:O,1,0)),"原型有新系统没有","") | L11: =IF(ISERROR(VLOOKUP(P11,新系统!P:P,1,0)),"原型有新系统没有","") | M11: =IF(ISERROR(VLOOKUP(Q11,新系统!Q:Q,1,0)),"原型有新系统没有","") | N11: =IF(ISERROR(VLOOKUP(R11,新系统!R:R,1,0)),"原型有新系统没有","") | O11: 金融质押品 | P11: 债券 | Q11: 国债 | R11: 凭证国债
A12: 金融质押品 | B12: 债券 | C12: 国债 | D12: 记账式国债 | E12: =CLEAN(A12)&"|"&CLEAN(B12)&"|"&CLEAN(C12)&"|"&CLEAN(D12) -> 金融质押品|债券|国债|记账式国债 | F12: =CLEAN(B12)&"|"&CLEAN(C12)&"|"&CLEAN(D12) -> 债券|国债|记账式国债 | G12: =CLEAN(C12)&"|"&CLEAN(D12) -> 国债|记账式国债 | H12: =IF(ISERROR(VLOOKUP(E12,新系统!E:E,1,0)),"原型有新系统没有","") | I12: =IF(ISERROR(VLOOKUP(F12,新系统!F:F,1,0)),"原型有新系统没有","") | J12: =IF(ISERROR(VLOOKUP(G12,新系统!G:G,1,0)),"原型有新系统没有","") | K12: =IF(ISERROR(VLOOKUP(O12,新系统!O:O,1,0)),"原型有新系统没有","") | L12: =IF(ISERROR(VLOOKUP(P12,新系统!P:P,1,0)),"原型有新系统没有","") | M12: =IF(ISERROR(VLOOKUP(Q12,新系统!Q:Q,1,0)),"原型有新系统没有","") | N12: =IF(ISERROR(VLOOKUP(R12,新系统!R:R,1,0)),"原型有新系统没有","") | O12: 金融质押品 | P12: 债券 | Q12: 国债 | R12: 记账式国债
A13: 金融质押品 | B13: 债券 | C13: 地方政府债券 | D13: 境内地方债 | E13: =CLEAN(A13)&"|"&CLEAN(B13)&"|"&CLEAN(C13)&"|"&CLEAN(D13) -> 金融质押品|债券|地方政府债券|境内地方债 | F13: =CLEAN(B13)&"|"&CLEAN(C13)&"|"&CLEAN(D13) -> 债券|地方政府债券|境内地方债 | G13: =CLEAN(C13)&"|"&CLEAN(D13) -> 地方政府债券|境内地方债 | H13: =IF(ISERROR(VLOOKUP(E13,新系统!E:E,1,0)),"原型有新系统没有","") | I13: =IF(ISERROR(VLOOKUP(F13,新系统!F:F,1,0)),"原型有新系统没有","") | J13: =IF(ISERROR(VLOOKUP(G13,新系统!G:G,1,0)),"原型有新系统没有","") | K13: =IF(ISERROR(VLOOKUP(O13,新系统!O:O,1,0)),"原型有新系统没有","") | L13: =IF(ISERROR(VLOOKUP(P13,新系统!P:P,1,0)),"原型有新系统没有","") | M13: =IF(ISERROR(VLOOKUP(Q13,新系统!Q:Q,1,0)),"原型有新系统没有","") | N13: =IF(ISERROR(VLOOKUP(R13,新系统!R:R,1,0)),"原型有新系统没有","") | O13: 金融质押品 | P13: 债券 | Q13: 地方政府债券 | R13: 境内地方债
... A133: 其他押品 | B133: 其他以上未包括的押品 | C133: 其他以上未包括的押品 | D133: 其他以上未包括的押品 | E133: =CLEAN(A133)&"|"&CLEAN(B133)&"|"&CLEAN(C133)&"|"&CLEAN(D133) -> 其他押品|其他以上未包括的押品|其他以上未包括的押品|其他以上未包括的押品 | F133: =CLEAN(B133)&"|"&CLEAN(C133)&"|"&CLEAN(D133) -> 其他以上未包括的押品|其他以上未包括的押品|其他以上未包括的押品 | G133: =CLEAN(C133)&"|"&CLEAN(D133) -> 其他以上未包括的押品|其他以上未包括的押品 | H133: =IF(ISERROR(VLOOKUP(E133,新系统!E:E,1,0)),"原型有新系统没有","") -> 原型有新系统没有 | I133: =IF(ISERROR(VLOOKUP(F133,新系统!F:F,1,0)),"原型有新系统没有","") -> 原型有新系统没有 | J133: =IF(ISERROR(VLOOKUP(G133,新系统!G:G,1,0)),"原型有新系统没有","") -> 原型有新系统没有 | K133: =IF(ISERROR(VLOOKUP(O133,新系统!O:O,1,0)),"原型有新系统没有","") | L133: =IF(ISERROR(VLOOKUP(P133,新系统!P:P,1,0)),"原型有新系统没有","") -> 原型有新系统没有 | M133: =IF(ISERROR(VLOOKUP(Q133,新系统!Q:Q,1,0)),"原型有新系统没有","") -> 原型有新系统没有 | N133: =IF(ISERROR(VLOOKUP(R133,新系统!R:R,1,0)),"原型有新系统没有","") -> 原型有新系统没有 | O133: 其他押品 | P133: 其他以上未包括的押品 | Q133: 其他以上未包括的押品 | R133: 其他以上未包括的押品
L134: =IF(ISERROR(VLOOKUP(P134,新系统!P:P,1,0)),"原型有新系统没有","") -> 原型有新系统没有
A138: 1、准入押品目录中区分了表内表外业务的押品且抵质押率不同，是否需要增加押品分类； 2、准入押品目录二级、三级分类、四级分类与原型有差距，如债券中的三级和四级分类；房地产和其他押品中的二、三、四级分类； 3、部分押品分类准入目录中有，新系统中没有或者新系统中有，准入目录没有，需确认； | B138: 1、准入押品目录中区分了表内表外业务的押品且抵质押率不同，是否需要增加押品分类； 2、准入押品目录二级、三级分类、四级分类与原型有差距，如债券中的三级和四级分类；房地产和其他押品中的二、三、四级分类； 3、部分押品分类准入目录中有，新系统中没有或者新系统中有，准入目录没有，需确认； | C138: 1、准入押品目录中区分了表内表外业务的押品且抵质押率不同，是否需要增加押品分类； 2、准入押品目录二级、三级分类、四级分类与原型有差距，如债券中的三级和四级分类；房地产和其他押品中的二、三、四级分类； 3、部分押品分类准入目录中有，新系统中没有或者新系统中有，准入目录没有，需确认；
A139: 1、准入押品目录中区分了表内表外业务的押品且抵质押率不同，是否需要增加押品分类； 2、准入押品目录二级、三级分类、四级分类与原型有差距，如债券中的三级和四级分类；房地产和其他押品中的二、三、四级分类； 3、部分押品分类准入目录中有，新系统中没有或者新系统中有，准入目录没有，需确认； | B139: 1、准入押品目录中区分了表内表外业务的押品且抵质押率不同，是否需要增加押品分类； 2、准入押品目录二级、三级分类、四级分类与原型有差距，如债券中的三级和四级分类；房地产和其他押品中的二、三、四级分类； 3、部分押品分类准入目录中有，新系统中没有或者新系统中有，准入目录没有，需确认； | C139: 1、准入押品目录中区分了表内表外业务的押品且抵质押率不同，是否需要增加押品分类； 2、准入押品目录二级、三级分类、四级分类与原型有差距，如债券中的三级和四级分类；房地产和其他押品中的二、三、四级分类； 3、部分押品分类准入目录中有，新系统中没有或者新系统中有，准入目录没有，需确认；
A140: 1、准入押品目录中区分了表内表外业务的押品且抵质押率不同，是否需要增加押品分类； 2、准入押品目录二级、三级分类、四级分类与原型有差距，如债券中的三级和四级分类；房地产和其他押品中的二、三、四级分类； 3、部分押品分类准入目录中有，新系统中没有或者新系统中有，准入目录没有，需确认； | B140: 1、准入押品目录中区分了表内表外业务的押品且抵质押率不同，是否需要增加押品分类； 2、准入押品目录二级、三级分类、四级分类与原型有差距，如债券中的三级和四级分类；房地产和其他押品中的二、三、四级分类； 3、部分押品分类准入目录中有，新系统中没有或者新系统中有，准入目录没有，需确认； | C140: 1、准入押品目录中区分了表内表外业务的押品且抵质押率不同，是否需要增加押品分类； 2、准入押品目录二级、三级分类、四级分类与原型有差距，如债券中的三级和四级分类；房地产和其他押品中的二、三、四级分类； 3、部分押品分类准入目录中有，新系统中没有或者新系统中有，准入目录没有，需确认；
A141: 1、准入押品目录中区分了表内表外业务的押品且抵质押率不同，是否需要增加押品分类； 2、准入押品目录二级、三级分类、四级分类与原型有差距，如债券中的三级和四级分类；房地产和其他押品中的二、三、四级分类； 3、部分押品分类准入目录中有，新系统中没有或者新系统中有，准入目录没有，需确认； | B141: 1、准入押品目录中区分了表内表外业务的押品且抵质押率不同，是否需要增加押品分类； 2、准入押品目录二级、三级分类、四级分类与原型有差距，如债券中的三级和四级分类；房地产和其他押品中的二、三、四级分类； 3、部分押品分类准入目录中有，新系统中没有或者新系统中有，准入目录没有，需确认； | C141: 1、准入押品目录中区分了表内表外业务的押品且抵质押率不同，是否需要增加押品分类； 2、准入押品目录二级、三级分类、四级分类与原型有差距，如债券中的三级和四级分类；房地产和其他押品中的二、三、四级分类； 3、部分押品分类准入目录中有，新系统中没有或者新系统中有，准入目录没有，需确认；
A142: 1、准入押品目录中区分了表内表外业务的押品且抵质押率不同，是否需要增加押品分类； 2、准入押品目录二级、三级分类、四级分类与原型有差距，如债券中的三级和四级分类；房地产和其他押品中的二、三、四级分类； 3、部分押品分类准入目录中有，新系统中没有或者新系统中有，准入目录没有，需确认； | B142: 1、准入押品目录中区分了表内表外业务的押品且抵质押率不同，是否需要增加押品分类； 2、准入押品目录二级、三级分类、四级分类与原型有差距，如债券中的三级和四级分类；房地产和其他押品中的二、三、四级分类； 3、部分押品分类准入目录中有，新系统中没有或者新系统中有，准入目录没有，需确认； | C142: 1、准入押品目录中区分了表内表外业务的押品且抵质押率不同，是否需要增加押品分类； 2、准入押品目录二级、三级分类、四级分类与原型有差距，如债券中的三级和四级分类；房地产和其他押品中的二、三、四级分类； 3、部分押品分类准入目录中有，新系统中没有或者新系统中有，准入目录没有，需确认；
A143: 1、准入押品目录中区分了表内表外业务的押品且抵质押率不同，是否需要增加押品分类； 2、准入押品目录二级、三级分类、四级分类与原型有差距，如债券中的三级和四级分类；房地产和其他押品中的二、三、四级分类； 3、部分押品分类准入目录中有，新系统中没有或者新系统中有，准入目录没有，需确认； | B143: 1、准入押品目录中区分了表内表外业务的押品且抵质押率不同，是否需要增加押品分类； 2、准入押品目录二级、三级分类、四级分类与原型有差距，如债券中的三级和四级分类；房地产和其他押品中的二、三、四级分类； 3、部分押品分类准入目录中有，新系统中没有或者新系统中有，准入目录没有，需确认； | C143: 1、准入押品目录中区分了表内表外业务的押品且抵质押率不同，是否需要增加押品分类； 2、准入押品目录二级、三级分类、四级分类与原型有差距，如债券中的三级和四级分类；房地产和其他押品中的二、三、四级分类； 3、部分押品分类准入目录中有，新系统中没有或者新系统中有，准入目录没有，需确认；
A144: 1、准入押品目录中区分了表内表外业务的押品且抵质押率不同，是否需要增加押品分类； 2、准入押品目录二级、三级分类、四级分类与原型有差距，如债券中的三级和四级分类；房地产和其他押品中的二、三、四级分类； 3、部分押品分类准入目录中有，新系统中没有或者新系统中有，准入目录没有，需确认； | B144: 1、准入押品目录中区分了表内表外业务的押品且抵质押率不同，是否需要增加押品分类； 2、准入押品目录二级、三级分类、四级分类与原型有差距，如债券中的三级和四级分类；房地产和其他押品中的二、三、四级分类； 3、部分押品分类准入目录中有，新系统中没有或者新系统中有，准入目录没有，需确认； | C144: 1、准入押品目录中区分了表内表外业务的押品且抵质押率不同，是否需要增加押品分类； 2、准入押品目录二级、三级分类、四级分类与原型有差距，如债券中的三级和四级分类；房地产和其他押品中的二、三、四级分类； 3、部分押品分类准入目录中有，新系统中没有或者新系统中有，准入目录没有，需确认；
A145: 1、准入押品目录中区分了表内表外业务的押品且抵质押率不同，是否需要增加押品分类； 2、准入押品目录二级、三级分类、四级分类与原型有差距，如债券中的三级和四级分类；房地产和其他押品中的二、三、四级分类； 3、部分押品分类准入目录中有，新系统中没有或者新系统中有，准入目录没有，需确认； | B145: 1、准入押品目录中区分了表内表外业务的押品且抵质押率不同，是否需要增加押品分类； 2、准入押品目录二级、三级分类、四级分类与原型有差距，如债券中的三级和四级分类；房地产和其他押品中的二、三、四级分类； 3、部分押品分类准入目录中有，新系统中没有或者新系统中有，准入目录没有，需确认； | C145: 1、准入押品目录中区分了表内表外业务的押品且抵质押率不同，是否需要增加押品分类； 2、准入押品目录二级、三级分类、四级分类与原型有差距，如债券中的三级和四级分类；房地产和其他押品中的二、三、四级分类； 3、部分押品分类准入目录中有，新系统中没有或者新系统中有，准入目录没有，需确认；
A146: 1、准入押品目录中区分了表内表外业务的押品且抵质押率不同，是否需要增加押品分类； 2、准入押品目录二级、三级分类、四级分类与原型有差距，如债券中的三级和四级分类；房地产和其他押品中的二、三、四级分类； 3、部分押品分类准入目录中有，新系统中没有或者新系统中有，准入目录没有，需确认； | B146: 1、准入押品目录中区分了表内表外业务的押品且抵质押率不同，是否需要增加押品分类； 2、准入押品目录二级、三级分类、四级分类与原型有差距，如债券中的三级和四级分类；房地产和其他押品中的二、三、四级分类； 3、部分押品分类准入目录中有，新系统中没有或者新系统中有，准入目录没有，需确认； | C146: 1、准入押品目录中区分了表内表外业务的押品且抵质押率不同，是否需要增加押品分类； 2、准入押品目录二级、三级分类、四级分类与原型有差距，如债券中的三级和四级分类；房地产和其他押品中的二、三、四级分类； 3、部分押品分类准入目录中有，新系统中没有或者新系统中有，准入目录没有，需确认；

Sheet 新系统
A1: 一级菜单 | B1: 二级菜单 | C1: 三级菜单 | D1: 四级菜单 | E1: =CLEAN(A1)&"|"&CLEAN(B1)&"|"&CLEAN(C1)&"|"&CLEAN(D1) -> 一级菜单|二级菜单|三级菜单|四级菜单 | F1: =CLEAN(B1)&"|"&CLEAN(C1)&"|"&CLEAN(D1) -> 二级菜单|三级菜单|四级菜单 | G1: =CLEAN(C1)&"|"&CLEAN(D1) -> 三级菜单|四级菜单 | K1: 匹配1 | L1: 匹配2 | M1: 匹配3 | N1: 匹配4 | O1: 一级菜单 | P1: 二级菜单 | Q1: 三级菜单 | R1: 四级菜单
A2: 金融质押品 | B2: 现金及其等价物 | C2: 存单或存款 | D2: 我行存单 | E2: =CLEAN(A2)&"|"&CLEAN(B2)&"|"&CLEAN(C2)&"|"&CLEAN(D2) -> 金融质押品|现金及其等价物|存单或存款|我行存单 | F2: =CLEAN(B2)&"|"&CLEAN(C2)&"|"&CLEAN(D2) -> 现金及其等价物|存单或存款|我行存单 | G2: =CLEAN(C2)&"|"&CLEAN(D2) -> 存单或存款|我行存单 | H2: =IF(ISERROR(VLOOKUP(E2,原型!E:E,1,0)),"新系统有原型没有","") | K2: =IF(ISERROR(VLOOKUP(O2,原型!O:O,1,0)),"原型有新系统没有","") | L2: =IF(ISERROR(VLOOKUP(P2,原型!P:P,1,0)),"原型有新系统没有","") | M2: =IF(ISERROR(VLOOKUP(Q2,原型!Q:Q,1,0)),"原型有新系统没有","") | N2: =IF(ISERROR(VLOOKUP(R2,原型!R:R,1,0)),"原型有新系统没有","") | O2: 金融质押品 | P2: 现金及其等价物 | Q2: 存单或存款 | R2: 我行存单
A3: 金融质押品 | B3: 现金及其等价物 | C3: 存单或存款 | D3: 他行存单 | E3: =CLEAN(A3)&"|"&CLEAN(B3)&"|"&CLEAN(C3)&"|"&CLEAN(D3) -> 金融质押品|现金及其等价物|存单或存款|他行存单 | F3: =CLEAN(B3)&"|"&CLEAN(C3)&"|"&CLEAN(D3) -> 现金及其等价物|存单或存款|他行存单 | G3: =CLEAN(C3)&"|"&CLEAN(D3) -> 存单或存款|他行存单 | H3: =IF(ISERROR(VLOOKUP(E3,原型!E:E,1,0)),"新系统有原型没有","") | K3: =IF(ISERROR(VLOOKUP(O3,原型!O:O,1,0)),"原型有新系统没有","") | L3: =IF(ISERROR(VLOOKUP(P3,原型!P:P,1,0)),"原型有新系统没有","") | M3: =IF(ISERROR(VLOOKUP(Q3,原型!Q:Q,1,0)),"原型有新系统没有","") | N3: =IF(ISERROR(VLOOKUP(R3,原型!R:R,1,0)),"原型有新系统没有","") | O3: 金融质押品 | P3: 现金及其等价物 | Q3: 存单或存款 | R3: 他行存单
A4: 金融质押品 | B4: 现金及其等价物 | C4: 保证金 | D4: 保证金 | E4: =CLEAN(A4)&"|"&CLEAN(B4)&"|"&CLEAN(C4)&"|"&CLEAN(D4) -> 金融质押品|现金及其等价物|保证金|保证金 | F4: =CLEAN(B4)&"|"&CLEAN(C4)&"|"&CLEAN(D4) -> 现金及其等价物|保证金|保证金 | G4: =CLEAN(C4)&"|"&CLEAN(D4) -> 保证金|保证金 | H4: =IF(ISERROR(VLOOKUP(E4,原型!E:E,1,0)),"新系统有原型没有","") | K4: =IF(ISERROR(VLOOKUP(O4,原型!O:O,1,0)),"原型有新系统没有","") | L4: =IF(ISERROR(VLOOKUP(P4,原型!P:P,1,0)),"原型有新系统没有","") | M4: =IF(ISERROR(VLOOKUP(Q4,原型!Q:Q,1,0)),"原型有新系统没有","") | N4: =IF(ISERROR(VLOOKUP(R4,原型!R:R,1,0)),"原型有新系统没有","") | O4: 金融质押品 | P4: 现金及其等价物 | Q4: 保证金 | R4: 保证金
A5: 金融质押品 | B5: 贵金属 | C5: 我行出售的贵金属 | D5: 我行出售的贵金属 | E5: =CLEAN(A5)&"|"&CLEAN(B5)&"|"&CLEAN(C5)&"|"&CLEAN(D5) -> 金融质押品|贵金属|我行出售的贵金属|我行出售的贵金属 | F5: =CLEAN(B5)&"|"&CLEAN(C5)&"|"&CLEAN(D5) -> 贵金属|我行出售的贵金属|我行出售的贵金属 | G5: =CLEAN(C5)&"|"&CLEAN(D5) -> 我行出售的贵金属|我行出售的贵金属 | H5: =IF(ISERROR(VLOOKUP(E5,原型!E:E,1,0)),"新系统有原型没有","") | K5: =IF(ISERROR(VLOOKUP(O5,原型!O:O,1,0)),"原型有新系统没有","") | L5: =IF(ISERROR(VLOOKUP(P5,原型!P:P,1,0)),"原型有新系统没有","") | M5: =IF(ISERROR(VLOOKUP(Q5,原型!Q:Q,1,0)),"原型有新系统没有","") | N5: =IF(ISERROR(VLOOKUP(R5,原型!R:R,1,0)),"原型有新系统没有","") | O5: 金融质押品 | P5: 贵金属 | Q5: 我行出售的贵金属 | R5: 我行出售的贵金属
A6: 金融质押品 | B6: 贵金属 | C6: 金交所托管的贵金属 | D6: 黄金 | E6: =CLEAN(A6)&"|"&CLEAN(B6)&"|"&CLEAN(C6)&"|"&CLEAN(D6) -> 金融质押品|贵金属|金交所托管的贵金属|黄金 | F6: =CLEAN(B6)&"|"&CLEAN(C6)&"|"&CLEAN(D6) -> 贵金属|金交所托管的贵金属|黄金 | G6: =CLEAN(C6)&"|"&CLEAN(D6) -> 金交所托管的贵金属|黄金 | H6: =IF(ISERROR(VLOOKUP(E6,原型!E:E,1,0)),"新系统有原型没有","") | K6: =IF(ISERROR(VLOOKUP(O6,原型!O:O,1,0)),"原型有新系统没有","") | L6: =IF(ISERROR(VLOOKUP(P6,原型!P:P,1,0)),"原型有新系统没有","") | M6: =IF(ISERROR(VLOOKUP(Q6,原型!Q:Q,1,0)),"原型有新系统没有","") | N6: =IF(ISERROR(VLOOKUP(R6,原型!R:R,1,0)),"原型有新系统没有","") | O6: 金融质押品 | P6: 贵金属 | Q6: 金交所托管的贵金属 | R6: 黄金
A7: 金融质押品 | B7: 贵金属 | C7: 金交所托管的贵金属 | D7: 标准银、铂金等其他贵金属 | E7: =CLEAN(A7)&"|"&CLEAN(B7)&"|"&CLEAN(C7)&"|"&CLEAN(D7) -> 金融质押品|贵金属|金交所托管的贵金属|标准银、铂金等其他贵金属 | F7: =CLEAN(B7)&"|"&CLEAN(C7)&"|"&CLEAN(D7) -> 贵金属|金交所托管的贵金属|标准银、铂金等其他贵金属 | G7: =CLEAN(C7)&"|"&CLEAN(D7) -> 金交所托管的贵金属|标准银、铂金等其他贵金属 | H7: =IF(ISERROR(VLOOKUP(E7,原型!E:E,1,0)),"新系统有原型没有","") | K7: =IF(ISERROR(VLOOKUP(O7,原型!O:O,1,0)),"原型有新系统没有","") | L7: =IF(ISERROR(VLOOKUP(P7,原型!P:P,1,0)),"原型有新系统没有","") | M7: =IF(ISERROR(VLOOKUP(Q7,原型!Q:Q,1,0)),"原型有新系统没有","") | N7: =IF(ISERROR(VLOOKUP(R7,原型!R:R,1,0)),"原型有新系统没有","") | O7: 金融质押品 | P7: 贵金属 | Q7: 金交所托管的贵金属 | R7: 标准银铂金等其他贵金属
A8: 金融质押品 | B8: 同业存单 | C8: 同业存单 | D8: 同业存单 | E8: =CLEAN(A8)&"|"&CLEAN(B8)&"|"&CLEAN(C8)&"|"&CLEAN(D8) -> 金融质押品|同业存单|同业存单|同业存单 | F8: =CLEAN(B8)&"|"&CLEAN(C8)&"|"&CLEAN(D8) -> 同业存单|同业存单|同业存单 | G8: =CLEAN(C8)&"|"&CLEAN(D8) -> 同业存单|同业存单 | H8: =IF(ISERROR(VLOOKUP(E8,原型!E:E,1,0)),"新系统有原型没有","") | K8: =IF(ISERROR(VLOOKUP(O8,原型!O:O,1,0)),"原型有新系统没有","") | L8: =IF(ISERROR(VLOOKUP(P8,原型!P:P,1,0)),"原型有新系统没有","") | M8: =IF(ISERROR(VLOOKUP(Q8,原型!Q:Q,1,0)),"原型有新系统没有","") | N8: =IF(ISERROR(VLOOKUP(R8,原型!R:R,1,0)),"原型有新系统没有","") | O8: 金融质押品 | P8: 同业存单 | Q8: 同业存单 | R8: 同业存单
A9: 金融质押品 | B9: 债券 | C9: 国债 | D9: 储蓄国债 | E9: =CLEAN(A9)&"|"&CLEAN(B9)&"|"&CLEAN(C9)&"|"&CLEAN(D9) -> 金融质押品|债券|国债|储蓄国债 | F9: =CLEAN(B9)&"|"&CLEAN(C9)&"|"&CLEAN(D9) -> 债券|国债|储蓄国债 | G9: =CLEAN(C9)&"|"&CLEAN(D9) -> 国债|储蓄国债 | H9: =IF(ISERROR(VLOOKUP(E9,原型!E:E,1,0)),"新系统有原型没有","") | K9: =IF(ISERROR(VLOOKUP(O9,原型!O:O,1,0)),"原型有新系统没有","") | L9: =IF(ISERROR(VLOOKUP(P9,原型!P:P,1,0)),"原型有新系统没有","") | M9: =IF(ISERROR(VLOOKUP(Q9,原型!Q:Q,1,0)),"原型有新系统没有","") | N9: =IF(ISERROR(VLOOKUP(R9,原型!R:R,1,0)),"原型有新系统没有","") | O9: 金融质押品 | P9: 债券 | Q9: 国债 | R9: 储蓄国债
A10: 金融质押品 | B10: 债券 | C10: 国债 | D10: 凭证国债 | E10: =CLEAN(A10)&"|"&CLEAN(B10)&"|"&CLEAN(C10)&"|"&CLEAN(D10) -> 金融质押品|债券|国债|凭证国债 | F10: =CLEAN(B10)&"|"&CLEAN(C10)&"|"&CLEAN(D10) -> 债券|国债|凭证国债 | G10: =CLEAN(C10)&"|"&CLEAN(D10) -> 国债|凭证国债 | H10: =IF(ISERROR(VLOOKUP(E10,原型!E:E,1,0)),"新系统有原型没有","") | K10: =IF(ISERROR(VLOOKUP(O10,原型!O:O,1,0)),"原型有新系统没有","") | L10: =IF(ISERROR(VLOOKUP(P10,原型!P:P,1,0)),"原型有新系统没有","") | M10: =IF(ISERROR(VLOOKUP(Q10,原型!Q:Q,1,0)),"原型有新系统没有","") | N10: =IF(ISERROR(VLOOKUP(R10,原型!R:R,1,0)),"原型有新系统没有","") | O10: 金融质押品 | P10: 债券 | Q10: 国债 | R10: 凭证国债
A11: 金融质押品 | B11: 债券 | C11: 国债 | D11: 记账式国债 | E11: =CLEAN(A11)&"|"&CLEAN(B11)&"|"&CLEAN(C11)&"|"&CLEAN(D11) -> 金融质押品|债券|国债|记账式国债 | F11: =CLEAN(B11)&"|"&CLEAN(C11)&"|"&CLEAN(D11) -> 债券|国债|记账式国债 | G11: =CLEAN(C11)&"|"&CLEAN(D11) -> 国债|记账式国债 | H11: =IF(ISERROR(VLOOKUP(E11,原型!E:E,1,0)),"新系统有原型没有","") | K11: =IF(ISERROR(VLOOKUP(O11,原型!O:O,1,0)),"原型有新系统没有","") | L11: =IF(ISERROR(VLOOKUP(P11,原型!P:P,1,0)),"原型有新系统没有","") | M11: =IF(ISERROR(VLOOKUP(Q11,原型!Q:Q,1,0)),"原型有新系统没有","") | N11: =IF(ISERROR(VLOOKUP(R11,原型!R:R,1,0)),"原型有新系统没有","") | O11: 金融质押品 | P11: 债券 | Q11: 国债 | R11: 记账式国债
A12: 金融质押品 | B12: 债券 | C12: 央票 | D12: 央行票据 | E12: =CLEAN(A12)&"|"&CLEAN(B12)&"|"&CLEAN(C12)&"|"&CLEAN(D12) -> 金融质押品|债券|央票|央行票据 | F12: =CLEAN(B12)&"|"&CLEAN(C12)&"|"&CLEAN(D12) -> 债券|央票|央行票据 | G12: =CLEAN(C12)&"|"&CLEAN(D12) -> 央票|央行票据 | H12: =IF(ISERROR(VLOOKUP(E12,原型!E:E,1,0)),"新系统有原型没有","") | K12: =IF(ISERROR(VLOOKUP(O12,原型!O:O,1,0)),"原型有新系统没有","") | L12: =IF(ISERROR(VLOOKUP(P12,原型!P:P,1,0)),"原型有新系统没有","") | M12: =IF(ISERROR(VLOOKUP(Q12,原型!Q:Q,1,0)),"原型有新系统没有","") | N12: =IF(ISERROR(VLOOKUP(R12,原型!R:R,1,0)),"原型有新系统没有","") | O12: 金融质押品 | P12: 债券 | Q12: 央票 | R12: 央行票据
A13: 金融质押品 | B13: 债券 | C13: 地方政府债券 | D13: 境内地方债 | E13: =CLEAN(A13)&"|"&CLEAN(B13)&"|"&CLEAN(C13)&"|"&CLEAN(D13) -> 金融质押品|债券|地方政府债券|境内地方债 | F13: =CLEAN(B13)&"|"&CLEAN(C13)&"|"&CLEAN(D13) -> 债券|地方政府债券|境内地方债 | G13: =CLEAN(C13)&"|"&CLEAN(D13) -> 地方政府债券|境内地方债 | H13: =IF(ISERROR(VLOOKUP(E13,原型!E:E,1,0)),"新系统有原型没有","") | K13: =IF(ISERROR(VLOOKUP(O13,原型!O:O,1,0)),"原型有新系统没有","") | L13: =IF(ISERROR(VLOOKUP(P13,原型!P:P,1,0)),"原型有新系统没有","") | M13: =IF(ISERROR(VLOOKUP(Q13,原型!Q:Q,1,0)),"原型有新系统没有","") | N13: =IF(ISERROR(VLOOKUP(R13,原型!R:R,1,0)),"原型有新系统没有","") | O13: 金融质押品 | P13: 债券 | Q13: 地方政府债券 | R13: 境内地方债
... A114: 其他押品 | B114: 特殊建筑构造物 | C114: 储油罐 | D114: 储油罐 | E114: =CLEAN(A114)&"|"&CLEAN(B114)&"|"&CLEAN(C114)&"|"&CLEAN(D114) -> 其他押品|特殊建筑构造物|储油罐|储油罐 | F114: =CLEAN(B114)&"|"&CLEAN(C114)&"|"&CLEAN(D114) -> 特殊建筑构造物|储油罐|储油罐 | G114: =CLEAN(C114)&"|"&CLEAN(D114) -> 储油罐|储油罐 | H114: =IF(ISERROR(VLOOKUP(E114,原型!E:E,1,0)),"新系统有原型没有","") | K114: =IF(ISERROR(VLOOKUP(O114,原型!O:O,1,0)),"原型有新系统没有","") | L114: =IF(ISERROR(VLOOKUP(P114,原型!P:P,1,0)),"原型有新系统没有","") | M114: =IF(ISERROR(VLOOKUP(Q114,原型!Q:Q,1,0)),"原型有新系统没有","") | N114: =IF(ISERROR(VLOOKUP(R114,原型!R:R,1,0)),"原型有新系统没有","") | O114: 其他押品 | P114: 特殊建筑构造物 | Q114: 储油罐 | R114: 储油罐
A115: 其他押品 | B115: 特殊建筑构造物 | C115: 管道 | D115: 管道
C122: 储油罐

Sheet Sheet2
A1: `CLRTYPEID` | B1: `CLRTYPENAME` | C1: `PARENTNODEID` | D1: `ISLEAFNODE` | E1: `CLRTABLENAME` | F1: `TEMPLETNO`
A2: 10 | B2: 金融质押品 | D2: 2 | E2: CLR_ASSET_REALTY | F2: CLRRealtyBuilding
A3: 10010 | B3: 现金及其等价物 | C3: 10 | D3: 2
A4: 10010010 | B4: 存单或存款 | C4: 10010 | D4: 2
A5: 10010010010 | B5: 我行存单 | C5: 10010010 | D5: 1 | E5: CLR_ASSET_FINANCE | F5: CLRDespositInfo
A6: 10010010020 | B6: 他行存单 | C6: 10010010 | D6: 1 | E6: CLR_ASSET_FINANCE | F6: CLRDespositInfo
A7: 10010020 | B7: 保证金 | C7: 10010 | D7: 2
A8: 10010020010 | B8: 保证金 | C8: 10010020 | D8: 1 | E8: CLR_ASSET_FINANCE | F8: CLRCashInfo
A9: 10020 | B9: 贵金属 | C9: 10 | D9: 2
A10: 10020010 | B10: 我行出售的贵金属 | C10: 10020 | D10: 2
A11: 10020010010 | B11: 我行出售的贵金属 | C11: 10020010 | D11: 1 | E11: CLR_ASSET_FINANCE | F11: CLRPreciousInfo
A12: 10020020 | B12: 金交所托管的贵金属 | C12: 10020 | D12: 2
A13: 10020020010 | B13: 黄金 | C13: 10020020 | D13: 1 | E13: CLR_ASSET_FINANCE | F13: CLRPreciousInfo
A14: 10020020020 | B14: 标准银、铂金等其他贵金属 | C14: 10020020 | D14: 1 | E14: CLR_ASSET_FINANCE | F14: CLRPreciousInfo
A15: 10030 | B15: 同业存单 | C15: 10 | D15: 2
A16: 10030010 | B16: 同业存单 | C16: 10030 | D16: 2
A17: 10030010010 | B17: 同业存单 | C17: 10030010 | D17: 1 | E17: CLR_ASSET_FINANCE | F17: CLRDespositData
A18: 10040 | B18: 债券 | C18: 10 | D18: 2 | E18: CLR_ASSET_FINANCE
A19: 10040010 | B19: 国债 | C19: 10040 | D19: 2
A20: 10040010010 | B20: 储蓄国债 | C20: 10040010 | D20: 1 | E20: CLR_ASSET_FINANCE | F20: CLRBond
A21: 10040010020 | B21: 凭证国债 | C21: 10040010 | D21: 1 | E21: CLR_ASSET_FINANCE | F21: CLRBond
A22: 10040010030 | B22: 记账式国债 | C22: 10040010 | D22: 1 | E22: CLR_ASSET_FINANCE | F22: CLRBond
A23: 10040020 | B23: 央票 | C23: 10040 | D23: 2
A24: 10040020010 | B24: 央行票据 | C24: 10040020 | D24: 1 | E24: CLR_ASSET_FINANCE | F24: CLRBond
A25: 10040030 | B25: 地方债 | C25: 10040 | D25: 2
A26: 10040030010 | B26: 境内地方债 | C26: 10040030 | D26: 1 | E26: CLR_ASSET_FINANCE | F26: CLRBond
A27: 10040040 | B27: 金融债 | C27: 10040 | D27: 2
A28: 10040040010 | B28: 政策性金融债 | C28: 10040040 | D28: 1 | E28: CLR_ASSET_FINANCE | F28: CLRBond
A29: 10040040020 | B29: 其他金融债 | C29: 10040040 | D29: 1 | E29: CLR_ASSET_FINANCE | F29: CLRBond
A30: 10040050 | B30: 公司类债券 | C30: 10040 | D30: 2
A31: 10040050010 | B31: 商业银行企业债/公司债 | C31: 10040050 | D31: 1 | E31: CLR_ASSET_FINANCE | F31: CLRBond
A32: 10040050020 | B32: 非银行金融机构企业债/公司债 | C32: 10040050 | D32: 1 | E32: CLR_ASSET_FINANCE | F32: CLRBond
A33: 10040050030 | B33: 政府支持机构债 | C33: 10040050 | D33: 1 | E33: CLR_ASSET_FINANCE | F33: CLRBond
A34: 10040050040 | B34: 其他公司企业债/公司债 | C34: 10040050 | D34: 1 | E34: CLR_ASSET_FINANCE | F34: CLRBond
A35: 10040050050 | B35: 中期票据 | C35: 10040050 | D35: 1 | E35: CLR_ASSET_FINANCE | F35: CLRBond
A36: 10040050060 | B36: 短期融资券 | C36: 10040050 | D36: 1 | E36: CLR_ASSET_FINANCE | F36: CLRBond
A37: 10040060 | B37: 境外市场发行的债券 | C37: 10040 | D37: 2
A38: 10040060010 | B38: 境外市场发行的人民币债券 | C38: 10040060 | D38: 1 | E38: CLR_ASSET_FINANCE | F38: CLRBond
A39: 10040060020 | B39: 境外市场发行的外币债券 | C39: 10040060 | D39: 1 | E39: CLR_ASSET_FINANCE | F39: CLRBond
A40: 10050 | B40: 票据 | C40: 10 | D40: 2
...

Sheet 变更
A1: 商用房地产和居住用房地产 改为 房地产
A2: 可转让股票(权)/基金 改为 股票（权）/基金
A3: 实货存货 改为 实物存货
A4: 交易类应收账款 改为 普通应收账款（交易类）
A5: 其他商用房和居住用房地产 改为 其他房地产类押品
A6: 加油站 改为 加油（气）站
A7: 商用房产类在建工程 改为 经营性房产类在建工程
A8: 商用建设用地使用权 改为 经营性建设用地使用权
A9: 商用房地产 改为 商业用房地产
A10: 具有现金价值的人寿保险单 改为 保单
A11: 地方债 改为 地方政府债券
A12: 公司类债券 改为 非金融企业债
... A28: 以招标/拍卖/公开协商等方式取得的荒地(荒山/荒沟/荒丘/荒滩)的土地承包经营权 改为 其他资源资产

Sheet Sheet1
A1: 系统四级分类 | B1: 系统四级分类 | C1: 系统四级分类 | D1: 系统四级分类 | H1: 一级菜单 | I1: 二级菜单 | J1: 三级菜单 | K1: 四级菜单
A2: 一级分类 | B2: 二级分类 | C2: 三级分类 | D2: 四级分类 | H2: 金融质押品 | I2: 现金及其等价物 | J2: 存单或存款 | K2: 我行存单
A3: 金融质押品 | B3: 现金及其等价物 | C3: 存单或存款 | D3: 我行存单 | H3: 金融质押品 | I3: 现金及其等价物 | J3: 存单或存款 | K3: 他行存单
A4: 金融质押品 | B4: 现金及其等价物 | C4: 存单或存款 | D4: 他行存单 | H4: 金融质押品 | I4: 现金及其等价物 | J4: 保证金 | K4: 保证金
A5: 金融质押品 | B5: 现金及其等价物 | C5: 保证金 | D5: 保证金 | H5: 金融质押品 | I5: 贵金属 | J5: 我行出售的贵金属 | K5: 我行出售的贵金属
A6: 金融质押品 | B6: 贵金属 | C6: 我行出售的贵金属 | D6: 我行出售的贵金属 | H6: 金融质押品 | I6: 贵金属 | J6: 金交所托管的贵金属 | K6: 黄金
A7: 金融质押品 | B7: 贵金属 | C7: 金交所托管的贵金属 | D7: 黄金 | H7: 金融质押品 | I7: 贵金属 | J7: 金交所托管的贵金属 | K7: 标准银铂金等其他贵金属
A8: 金融质押品 | B8: 贵金属 | C8: 金交所托管的贵金属 | D8: 标准银铂金等其他贵金属 | H8: 金融质押品 | I8: 同业存单 | J8: 同业存单 | K8: 同业存单
A9: 金融质押品 | B9: 同业存单 | C9: 同业存单 | D9: 同业存单 | H9: 金融质押品 | I9: 债券 | J9: 国债 | K9: 储蓄国债
A10: 金融质押品 | B10: 债券 | C10: 国债 | D10: 储蓄国债 | H10: 金融质押品 | I10: 债券 | J10: 国债 | K10: 凭证国债
A11: 金融质押品 | B11: 债券 | C11: 国债 | D11: 凭证国债 | H11: 金融质押品 | I11: 债券 | J11: 国债 | K11: 记账式国债
A12: 金融质押品 | B12: 债券 | C12: 国债 | D12: 记账式国债 | H12: 金融质押品 | I12: 债券 | J12: 央票 | K12: 央行票据
... A115: 其他押品 | B115: 资源资产 | C115: 碳排放权 | D115: 碳排放权 | H115: 金融质押品 | I115: 现金及其等价物 | J115: 存单或存款 | K115: 我行存单
A116: 其他押品 | B116: 资源资产 | C116: 排污权 | D116: 排污权
A117: 其他押品 | B117: 可转让知识产权中的财产权 | C117: 注册商标专用权 | D117: 注册商标专用权
A118: 其他押品 | B118: 可转让知识产权中的财产权 | C118: 专利权 | D118: 专利权
A119: 其他押品 | B119: 可转让知识产权中的财产权 | C119: 著作权 | D119: 著作权
A120: 其他押品 | B120: 可转让知识产权中的财产权 | C120: 其他知识产权 | D120: 其他知识产权
A121: 其他押品 | B121: 特殊建筑构造物 | C121: 车位车库 | D121: 车位车库
A122: 其他押品 | B122: 特殊建筑构造物 | C122: 加油气站 | D122: 加油气站
A123: 其他押品 | B123: 特殊建筑构造物 | C123: 铁路 | D123: 铁路
A124: 其他押品 | B124: 特殊建筑构造物 | C124: 机场 | D124: 机场
A125: 其他押品 | B125: 特殊建筑构造物 | C125: 码头 | D125: 码头
A126: 其他押品 | B126: 特殊建筑构造物 | C126: 港口 | D126: 港口
A127: 其他押品 | B127: 特殊建筑构造物 | C127: 公路 | D127: 公路
... A133: 其他押品 | B133: 其他以上未包括的押品 | C133: 其他以上未包括的押品 | D133: 其他以上未包括的押品

Sheet 外汇-与存单合并
B1: 返回目录
B2: 数据项名称 | C2: 数据项格式 | D2: 数据项代码值 | E2: 数据项来源 | F2: 数据项业务含义 | G2: 数据项应用场景要求 | H2: 数据项必输性校验要求 | I2: 数据唯一性识别要求 | K2: 备注 | L2: 码值 | M2: 字段名 | N2: 是否必输 | O2: 代码值
I3: 核心识别要素 | J3: 辅助识别要素
B4: 质押外汇帐户帐号 | E4: 押品数据标准模型 | L4: GuarantyRightID
B5: 外汇存款类型 | D5: 见代码表 | L5: ThirdParty1 | N5: 是
B6: 币种 | D6: 见代码表 | L6: ThirdParty2 | N6: 是
B7: 金额 | L7: GuarantyAmount | N7: 是
B8: 折人民币金额(按当前汇率) | L8: AboutSum1 | N8: 是
B10: 押品类型 | C10: getItemName('GuarantyList',GuarantyType) as GuarantyTypeName | D10: 质押物类型 | E10: 是
B11: 抵质押人信息 | C11: CertType | D11: 出质人证件类型 | F11: Ent04-营业执照(统一代码),Ind09-外国人居留证,Ent03-其他企业证件,Ind08-临时身份证,Ind10-警官证,Ind04-军官证,Ind02-户口簿,Ind05-士兵证,Ent01-组织机构代码证,Ind06-港澳居民来往内地通行证,Ind07-台湾同胞来往内地通行证,Ind01-身份证,Ent02-营业执照(旧版),Ind03-护照,Ind11-其他个人证件
B12: 抵质押人信息 | C12: CertID | D12: 出质人证件号码
B13: 抵质押人信息 | C13: OwnerName | D13: 出质人名称
B14: 抵质押人信息 | C14: LoanCardNo | D14: 出质人中征码(贷款卡号)
B15: 抵质押人信息 | C15: OwnerType | D15: 出质人类型 | F15: 06-自然人,07-其它,01-一般法人单位,02-专业担保公司,03-银行,04-保险公司,05-证券公司
B16: 抵质押人信息 | C16: WheaFirstSignee | D16: 是否第一抵押权人 | F16: 1-是,2-否
B17: 合格认定信息 | C17: GuarantyConvenAtt as GuarantyConvenAtt | D17: 查封便利性 | F17: 010-对于不动产无查封障碍，对于动产由我行监管,020-对于不动产查封有一定障碍，对于动产存放地点相对固定,030-对于不动产查封有障碍，对于动产存放地点难掌握和控制
B18: 合格认定信息 | C18: GuarantyEffAtt as GuarantyEffAtt | D18: 法律有效性 | F18: 010-抵押合法且依法登记,020-法律虽含糊但基本有效,030-抵押不合法或依法需登记未登记
B19: 合格认定信息 | C19: GuarantyRelateAtt as GuarantyRelateAtt | D19: 抵质押品与借款人第一还款来源的相关性 | F19: 010-无关,020-有一定相关性,030-高度相关,040-完全相关
B20: 合格认定信息 | C20: GuarantyBeMoneyAtt as GuarantyBeMoneyAtt | D20: 变现能力 | F20: 010-通用但变现较不易,020-通用且变现容易,030-专用性强,040-无法变现
B21: 合格认定信息 | C21: GuarantyValueAtt as GuarantyValueAtt | D21: 价值波动性 | F21: 010-有升值潜力或波动小,020-价值波动中,030-价值波动大,040-价值波动剧烈
B22: 价值信息 | C22: EvalCurrency | D22: 质押物币种 | E22: 是
B23: 价值信息 | C23: EvalNetValue | D23: 质押物金额 | E23: 是
B24: 价值信息 | C24: GuarantyCurrency | D24: 质押币种 | E24: 是
B25: 价值信息 | C25: ConfirmValue | D25: 质押金额 | E25: 是
B26: 公共信息 | C26: Remark | D26: 备注
B27: 公共信息 | C27: getUserName(InputUserID) as InputUserName | D27: 登记人
B28: 公共信息 | C28: getOrgName(InputOrgID) as InputOrgName | D28: 登记机构
B29: 公共信息 | C29: InputDate | D29: 登记日期
B30: 公共信息 | C30: UpdateDate | D30: 更新日期
B31: 公共信息 | C31: UserInPutDate | D31: 押品登记日期 | E31: 是
B32: 公共信息 | C32: UserInPutOrgName | D32: 押品登记机构 | E32: 是

Sheet 同业存单-与存单合并
B1: 返回目录
B2: 数据项名称 | C2: 数据项格式 | D2: 数据项代码值 | E2: 数据项来源 | F2: 数据项业务含义 | G2: 数据项应用场景要求 | H2: 数据项必输性校验要求 | I2: 数据唯一性识别要求 | K2: 备注
I3: 核心识别要素 | J3: 辅助识别要素
B4: 存单号 | C4: 编号(长度32) | E4: 押品数据标准模型 | F4: 表示存单的唯一性标示号码 | G4: 用户押品数据唯一性识别场景 | H4: ※ 必输 | I4: √
B5: 账号 | C5: 编号(长度32) | E5: 押品数据标准模型 | F5: 存单账号 | H5: ¤ 非必输 | K5: 如果是他行存单，则是否需要记录相应的存单账号信息
B6: 户名 | C6: 名称(长度80) | E6: 押品数据标准模型 | F6: 存单户名 | G6: 用于押品数据唯一性识别场景 | H6: ※ 必输 | J6: √
B7: 储蓄方式 | C7: 代码(长度2) | D7: 01.活期储蓄 02.整存整取 03.零存整取 04.整存零取 05.存本取息 06.定活两便 07.通知存款 08.其他 | E7: 押品数据标准模型 | F7: 表示存款的储蓄方式 | H7: ¤ 非必输
B8: 存单所属行行号 | C8: 代码(长度18) | D8: 详见人民银行发布的金融机构行号 | E8: 押品数据标准模型 | F8: 人民银行发布的金融机构行号 | G8: 用于押品数据唯一性识别场景 | H8: ※ 必输 | J8: √
B9: 存单所属行名称 | C9: 名称(长度80) | E9: 押品数据标准模型 | F9: 存单所属行名称 | H9: ※ 必输
B10: 币种 | C10: 代码(长度8) | D10: 详见代码表 | E10: 押品数据标准模型 | F10: 存单币种 | H10: ※ 必输
B11: 金额 | C11: 金额(长度24.6) | E11: 押品数据标准模型 | F11: 存单金额 | H11: ※ 必输
B12: 利率 | C12: 利率(长度10.6) | E12: 押品数据标准模型 | F12: 存单利率 | H12: ※ 必输
B13: 起息日期 | C13: 日期(长度10) | E13: 押品数据标准模型 | F13: 存款起息日期，一般情况下为存入日期的下一日期 | H13: ※ 必输
B14: 到期日期 | C14: 日期(长度10) | E14: 押品数据标准模型 | F14: 存款到期日期，通过存入日期与到期日期可以计算存单的存期 | H14: ※ 必输
B16: 是否有必要增加？

Sheet 商业承兑汇票-新增
B1: 返回目录
B2: 数据项名称 | C2: 数据项格式 | D2: 数据项代码值 | E2: 数据项来源 | F2: 数据项业务含义 | G2: 数据项应用场景要求 | H2: 数据项必须性校验要求 | I2: 数据唯一性识别要求 | K2: 备注 | L2: 码值 | M2: 字段名 | N2: 是否必输 | O2: 代码值
I3: 核心识别要素 | J3: 辅助识别要素
B4: 票据号 | C4: 编号(长度32) | E4: 押品数据标准模型 | G4: 用于押品数据唯一性识别场景 | H4: ※ 必须 | I4: √ | L4: GuarantyRightID | M4: 票据号码 | N4: 是
B5: 票据类型 | C5: 代码(长度2) | D5: 01.银行汇票 02.公共部门实体承兑汇票 03.银行本票 04.公共部门实体发行的本票 05.其他商业本票 06.支票 07.其他票据 | E5: 押品数据标准模型 | H5: ※ 必须 | L5: ThirdParty1 | M5: 票据类型 | N5: 是 | O5: 01-汇票,02-本票,03-支票
B6: 票面币种 | C6: 代码(长度8) | D6: 详见代码项 | E6: 押品数据标准模型 | H6: ※ 必须
B7: 票面金额 | C7: 金额(长度24.6) | E7: 押品数据标准模型 | H7: ※ 必须
B8: 签发日期 | C8: 日期(长度10) | E8: 押品数据标准模型 | H8: ※ 必须
B9: 出票日期 | C9: 日期(长度10) | E9: 押品数据标准模型 | H9: ※ 必须
B10: 到期日期 | C10: 日期(长度10) | E10: 押品数据标准模型 | H10: ※ 必须
B11: 票据用途 | C11: 代码(长度2) | D11: 01.转账 02.现金 | E11: 押品数据标准模型 | H11: ¤ 非必须
B12: 收款人 | C12: 名称(长度80) | E12: 押品数据标准模型 | F12: 收款人是指票据到期后有权收取票据所载金额的人，又称票据权利人，是票据的主债权人。收款人有权要求付款人付款，如果被拒绝付款，有权向出票人以及票据上的其它债务人追索票款。 | H12: ¤ 非必须
B13: 出票人 | C13: 名称(长度80) | E13: 押品数据标准模型 | F13: 出票人是开立票据并将其交付给他人的法人、其它组织或者个人。出票人对收款人及正当持票人承担票据在提示付款或承兑时必须付款或者承兑的保证责任。是指依法定方式签发票据并将票据交付给收款人的人。 | H13: ¤ 非必须 | L13: GuarantyName | M13: 出票人
B14: 出票人账号 | C14: 编号(长度32) | E14: 押品数据标准模型 | H14: ¤ 非必须
B15: 出票地 | C15: 属性集(长度320) | E15: 押品数据标准模型 | H15: ¤ 非必须
B16: 持票人 | C16: 名称(长度80) | E16: 押品数据标准模型 | F16: 持票人是指持有票据的人。持票人一般是收款人，但在特殊情形下，持票人与收款人也可能是不一致的。 | H16: ¤ 非必须
B17: 付款人 | C17: 名称(长度80) | E17: 押品数据标准模型 | H17: ¤ 非必须
B18: 付款地 | C18: 属性集(长度320) | E18: 押品数据标准模型 | H18: ¤ 非必须
B21: 押品类型 | C21: getItemName('GuarantyList',GuarantyType) as GuarantyTypeName | D21: 质押物类型
B22: 抵质押人信息 | C22: CertType | D22: 出质人证件类型 | F22: Ent04-营业执照(统一代码),Ind09-外国人居留证,Ent03-其他企业证件,Ind08-临时身份证,Ind10-警官证,Ind04-军官证,Ind02-户口簿,Ind05-士兵证,Ent01-组织机构代码证,Ind06-港澳居民来往内地通行证,Ind07-台湾同胞来往内地通行证,Ind01-身份证,Ent02-营业执照(旧版),Ind03-护照,Ind11-其他个人证件
B23: 抵质押人信息 | C23: CertID | D23: 出质人证件号码
B24: 抵质押人信息 | C24: OwnerName | D24: 出质人名称
B25: 抵质押人信息 | C25: LoanCardNo | D25: 出质人中征码(贷款卡号)
B26: 抵质押人信息 | C26: OwnerType | D26: 出质人类型 | F26: 06-自然人,07-其它,01-一般法人单位,02-专业担保公司,03-银行,04-保险公司,05-证券公司
B27: 抵质押人信息 | C27: WheaFirstSignee | D27: 是否第一抵押权人 | F27: 1-是,2-否
C28: IsSwitch | D28: 是否可转换债券 | F28: 1-是,2-否
C29: IsSWStock | D29: 转换的债券是否是主要指数股票 | F29: 1-是,2-否
C30: IsSWTrading | D30: 转换的债券是否在交易所挂牌 | F30: 1-是,2-否
C31: getItemName('IssuingEntity',IssuingEntity) as IssuingEntityName | D31: 发行主体机构
C32: getItemName('OutsideORG',OutsideORG) as OutsideORGName | D32: 外部评级机构
C33: OutsideGrade | D33: 外部评级结果区间 | F33: 1-AA-（含）以上或P-1/A-1/A-1+/F1/F1+,2-AA-（不含）至BBB-（含）或A-2/A-3/P-2/P-3/F2/F3,3-BBB-（不含）至BB-（含）,4-BB-（不含）以下或A-3/P-3/F3（不含）以下
C34: IsofBank | D34: 是否银行发行 | F34: 1-是,2-否
C35: IsofTrading | D35: 是否交易所交易 | F35: 1-是,2-否
C36: IsDebtFirst | D36: 是否具有优先债务的性质 | F36: 1-是,2-否
C37: IsFluidity | D37: 是否具有充分的流动性 | F37: 1-是,2-否
C38: IsOverGrade | D38: 发行人发行的同一级别债券外部评级 | F38: 1-是,2-否
C39: IsofCountry | D39: 是否收购国有银行而定向发行的债券 | F39: 1-是,2-否
C40: GuarantyResouce | D40: 出票行 | E40: 是
C41: ThirdParty2 | D41: 付款人
C42: ThirdParty3 | D42: 付款行 | E42: 是
...
