Workbook

Sheet 表结构清单
B2: 数据表 | C2: 数据表名称 | D2: 表归类
B3: =HYPERLINK("#AUDIT_INFO!A1","AUDIT_INFO") | C3: 审计信息 | D3: 评估机构
B4: =HYPERLINK("#APPRAISAL_AGENCY!A1","APPRAISAL_AGENCY") | C4: 评估机构
B5: =HYPERLINK("#APPRAISAL_AGENCY_APPLY!A1","APPRAISAL_AGENCY_APPLY") | C5: 评估机构申请信息表
B6: =HYPERLINK("#APPRAISAL_AGENCY_APPRAISE!A1","APPRAISAL_AGENCY_APPRAISE") | C6: 评价调查信息管理
B7: =HYPERLINK("#APPRAISAL_AGENCY_COOPERATION!A1","APPRAISAL_AGENCY_COOPERATION") | C7: 评估机构合作协议
B8: =HYPERLINK("#APPRAISAL_AGENCY_EVENT!A1","APPRAISAL_AGENCY_EVENT") | C8: 评估机构事件表
B9: =HYPERLINK("#APPRAISAL_AGENCY_EXPENSES!A1","APPRAISAL_AGENCY_EXPENSES") | C9: 评估机构费用
B10: =HYPERLINK("#APPRAISAL_AGENCY_FILE!A1","APPRAISAL_AGENCY_FILE") | C10: 评级机构附件
B11: =HYPERLINK("#APPRAISAL_AGENCY_INFORMATION!A1","APPRAISAL_AGENCY_INFORMATION") | C11: 评估公司相关信息
B12: =HYPERLINK("#APPRAISAL_AGENCY_QUALIFICATION!A1","APPRAISAL_AGENCY_QUALIFICATION") | C12: 评估机构资质表
B13: =HYPERLINK("#APPRAISAL_APPLY_RELATIVE!A1","APPRAISAL_APPLY_RELATIVE") | C13: 评级机构申请关联表
B14: =HYPERLINK("#AWE_BIZFILE_INFO!A1","AWE_BIZFILE_INFO") | C14: 业务文件详情 | D14: 底层表
B15: =HYPERLINK("#AWE_DICT_ERRMSG!A1","AWE_DICT_ERRMSG") | C15: 系统错误报告
B16: =HYPERLINK("#AWE_DO_CATALOG!A1","AWE_DO_CATALOG") | C16: OW显示模板场景
B17: =HYPERLINK("#AWE_DO_COL_VALIDATE!A1","AWE_DO_COL_VALIDATE") | C17: DW字段验证规则
B18: =HYPERLINK("#AWE_DO_EVENT!A1","AWE_DO_EVENT") | C18: OW字段事件
B19: =HYPERLINK("#AWE_DO_FUNCTION!A1","AWE_DO_FUNCTION") | C19: OW脚本方法
B20: =HYPERLINK("#AWE_DO_GROUP!A1","AWE_DO_GROUP") | C20: OW分组信息
B21: =HYPERLINK("#AWE_DO_JS_FUNCTION!A1","AWE_DO_JS_FUNCTION") | C21: OW通用js方法
B22: =HYPERLINK("#AWE_DO_KEYFILTER!A1","AWE_DO_KEYFILTER") | C22: OW关键字查询
B23: =HYPERLINK("#AWE_DO_LIBRARY!A1","AWE_DO_LIBRARY") | C23: OW显示模板字段信息
B24: =HYPERLINK("#AWE_DO_MODES!A1","AWE_DO_MODES") | C24: OW显示模板样式表
B25: =HYPERLINK("#AWE_DO_VALIDATE!A1","AWE_DO_VALIDATE") | C25: 数据验证类
B26: =HYPERLINK("#AWE_DO_VALIDATE_CATALOG!A1","AWE_DO_VALIDATE_CATALOG") | C26: 数据验证业务分类
B27: =HYPERLINK("#AWE_DW_CONTEXT!A1","AWE_DW_CONTEXT") | C27: 显示模型上下文环境
B28: =HYPERLINK("#AWE_FUNCTION_INFO!A1","AWE_FUNCTION_INFO") | C28: 功能点信息
B29: =HYPERLINK("#AWE_FUNCTION_URL!A1","AWE_FUNCTION_URL") | C29: 功能点URL
B30: =HYPERLINK("#AWE_GROUP_CATALOG!A1","AWE_GROUP_CATALOG") | C30: 组合页面目录信息
B31: =HYPERLINK("#CODE_CATALOG!A1","CODE_CATALOG") | C31: 代码类别表;代码类别表
B32: =HYPERLINK("#CODE_LIBRARY!A1","CODE_LIBRARY") | C32: 代码表;代码库
B33: =HYPERLINK("#OBJECTTYPE_CATALOG!A1","OBJECTTYPE_CATALOG") | C33: 对象类型信息表
B34: =HYPERLINK("#OBJECTTYPE_RELA!A1","OBJECTTYPE_RELA") | C34: 对象关联信息表
B35: =HYPERLINK("#OBJECT_ATTRIBUTE!A1","OBJECT_ATTRIBUTE") | C35: 对象属性信息表
B36: =HYPERLINK("#OBJECT_MAXSN!A1","OBJECT_MAXSN") | C36: 系统流水表;系统流水号表
B37: =HYPERLINK("#ROLE_RIGHT!A1","ROLE_RIGHT") | C37: 角色权限表
B38: =HYPERLINK("#SECURITY_AUDIT!A1","SECURITY_AUDIT") | C38: 安全审计
B39: =HYPERLINK("#SELECT_CATALOG!A1","SELECT_CATALOG") | C39: 查询信息表
B40: =HYPERLINK("#USER_FAILEDLIST!A1","USER_FAILEDLIST") | C40: 用户登录失败表;用户痕迹表
B41: =HYPERLINK("#USER_LIST!A1","USER_LIST") | C41: 用户登录表;用户登录列表
...

Sheet 表结构清单 (2)
B2: 数据表 | C2: 数据表名称 | D2: 表归类
B3: =HYPERLINK("#AUDIT_INFO!A1","AUDIT_INFO") | C3: 审计信息 | D3: 评估机构
B4: =HYPERLINK("#APPRAISAL_AGENCY!A1","APPRAISAL_AGENCY") | C4: 评估机构
B5: =HYPERLINK("#APPRAISAL_AGENCY_APPLY!A1","APPRAISAL_AGENCY_APPLY") | C5: 评估机构申请信息表
B6: =HYPERLINK("#APPRAISAL_AGENCY_APPRAISE!A1","APPRAISAL_AGENCY_APPRAISE") | C6: 评价调查信息管理
B7: =HYPERLINK("#APPRAISAL_AGENCY_COOPERATION!A1","APPRAISAL_AGENCY_COOPERATION") | C7: 评估机构合作协议
B8: =HYPERLINK("#APPRAISAL_AGENCY_EVENT!A1","APPRAISAL_AGENCY_EVENT") | C8: 评估机构事件表
B9: =HYPERLINK("#APPRAISAL_AGENCY_EXPENSES!A1","APPRAISAL_AGENCY_EXPENSES") | C9: 评估机构费用
B10: =HYPERLINK("#APPRAISAL_AGENCY_FILE!A1","APPRAISAL_AGENCY_FILE") | C10: 评级机构附件
B11: =HYPERLINK("#APPRAISAL_AGENCY_INFORMATION!A1","APPRAISAL_AGENCY_INFORMATION") | C11: 评估公司相关信息
B12: =HYPERLINK("#APPRAISAL_AGENCY_QUALIFICATION!A1","APPRAISAL_AGENCY_QUALIFICATION") | C12: 评估机构资质表
B13: =HYPERLINK("#APPRAISAL_APPLY_RELATIVE!A1","APPRAISAL_APPLY_RELATIVE") | C13: 评级机构申请关联表
B14: =HYPERLINK("#AWE_BIZFILE_INFO!A1","AWE_BIZFILE_INFO") | C14: 业务文件详情 | D14: 底层表
B15: =HYPERLINK("#AWE_DICT_ERRMSG!A1","AWE_DICT_ERRMSG") | C15: 系统错误报告
B16: =HYPERLINK("#AWE_DO_CATALOG!A1","AWE_DO_CATALOG") | C16: OW显示模板场景
B17: =HYPERLINK("#AWE_DO_COL_VALIDATE!A1","AWE_DO_COL_VALIDATE") | C17: DW字段验证规则
B18: =HYPERLINK("#AWE_DO_EVENT!A1","AWE_DO_EVENT") | C18: OW字段事件
B19: =HYPERLINK("#AWE_DO_FUNCTION!A1","AWE_DO_FUNCTION") | C19: OW脚本方法
B20: =HYPERLINK("#AWE_DO_GROUP!A1","AWE_DO_GROUP") | C20: OW分组信息
B21: =HYPERLINK("#AWE_DO_JS_FUNCTION!A1","AWE_DO_JS_FUNCTION") | C21: OW通用js方法
B22: =HYPERLINK("#AWE_DO_KEYFILTER!A1","AWE_DO_KEYFILTER") | C22: OW关键字查询
B23: =HYPERLINK("#AWE_DO_LIBRARY!A1","AWE_DO_LIBRARY") | C23: OW显示模板字段信息
B24: =HYPERLINK("#AWE_DO_MODES!A1","AWE_DO_MODES") | C24: OW显示模板样式表
B25: =HYPERLINK("#AWE_DO_VALIDATE!A1","AWE_DO_VALIDATE") | C25: 数据验证类
B26: =HYPERLINK("#AWE_DO_VALIDATE_CATALOG!A1","AWE_DO_VALIDATE_CATALOG") | C26: 数据验证业务分类
B27: =HYPERLINK("#AWE_DW_CONTEXT!A1","AWE_DW_CONTEXT") | C27: 显示模型上下文环境
B28: =HYPERLINK("#AWE_FUNCTION_INFO!A1","AWE_FUNCTION_INFO") | C28: 功能点信息
B29: =HYPERLINK("#AWE_FUNCTION_URL!A1","AWE_FUNCTION_URL") | C29: 功能点URL
B30: =HYPERLINK("#AWE_GROUP_CATALOG!A1","AWE_GROUP_CATALOG") | C30: 组合页面目录信息
B31: =HYPERLINK("#CODE_CATALOG!A1","CODE_CATALOG") | C31: 代码类别表;代码类别表
B32: =HYPERLINK("#CODE_LIBRARY!A1","CODE_LIBRARY") | C32: 代码表;代码库
B33: =HYPERLINK("#OBJECTTYPE_CATALOG!A1","OBJECTTYPE_CATALOG") | C33: 对象类型信息表
B34: =HYPERLINK("#OBJECTTYPE_RELA!A1","OBJECTTYPE_RELA") | C34: 对象关联信息表
B35: =HYPERLINK("#OBJECT_ATTRIBUTE!A1","OBJECT_ATTRIBUTE") | C35: 对象属性信息表
B36: =HYPERLINK("#OBJECT_MAXSN!A1","OBJECT_MAXSN") | C36: 系统流水表;系统流水号表
B37: =HYPERLINK("#ROLE_RIGHT!A1","ROLE_RIGHT") | C37: 角色权限表
B38: =HYPERLINK("#SECURITY_AUDIT!A1","SECURITY_AUDIT") | C38: 安全审计
B39: =HYPERLINK("#SELECT_CATALOG!A1","SELECT_CATALOG") | C39: 查询信息表
B40: =HYPERLINK("#USER_FAILEDLIST!A1","USER_FAILEDLIST") | C40: 用户登录失败表;用户痕迹表
B41: =HYPERLINK("#USER_LIST!A1","USER_LIST") | C41: 用户登录表;用户登录列表
...

Sheet Sheet1
A1: AUDIT_INFO | B1: 审计信息
A2: APPRAISAL_AGENCY | B2: 评估机构
A3: APPRAISAL_AGENCY_APPLY | B3: 评估机构申请信息表
A4: APPRAISAL_AGENCY_APPRAISE | B4: 评价调查信息管理
A5: APPRAISAL_AGENCY_COOPERATION | B5: 评估机构合作协议
A6: APPRAISAL_AGENCY_EVENT | B6: 评估机构事件表
A7: APPRAISAL_AGENCY_EXPENSES | B7: 评估机构费用
A8: APPRAISAL_AGENCY_FILE | B8: 评级机构附件
A9: APPRAISAL_AGENCY_INFORMATION | B9: 评估公司相关信息
A10: APPRAISAL_AGENCY_QUALIFICATION | B10: 评估机构资质表
A11: APPRAISAL_APPLY_RELATIVE | B11: 评级机构申请关联表
A12: CLR_REGISTER_RECORD | B12: 抵质押登记记录
... A70: CCMS_PARTYINF | B70: 支付系统—行名行号表
A71: 审计信息 | B71: AUDIT_INFO | C71: SERIALNO | D71: VARCHAR(32) | E71: NO | F71: 流水号 | H71: VARCHAR | I71: 32
A72: 审计信息 | B72: AUDIT_INFO | C72: OPERATOR | D72: VARCHAR(80) | E72: YES | F72: 操作人 | H72: VARCHAR | I72: 80
A73: 审计信息 | B73: AUDIT_INFO | C73: SERVERADDRESS | D73: VARCHAR(80) | E73: YES | F73: 服务器地址 | H73: VARCHAR | I73: 80
A74: 审计信息 | B74: AUDIT_INFO | C74: CLIENTADDRESS | D74: VARCHAR(80) | E74: YES | F74: 客户端地址 | H74: VARCHAR | I74: 80
A75: 审计信息 | B75: AUDIT_INFO | C75: APPLICATION | D75: VARCHAR(200) | E75: YES | F75: 应用 | H75: VARCHAR | I75: 200
A76: 审计信息 | B76: AUDIT_INFO | C76: ADDITIONALINFO | D76: VARCHAR(200) | E76: YES | F76: 附加信息 | H76: VARCHAR | I76: 200
A77: 审计信息 | B77: AUDIT_INFO | C77: RECORDTYPE | D77: VARCHAR(32) | E77: YES | F77: 记录类型 | H77: VARCHAR | I77: 32
A78: 审计信息 | B78: AUDIT_INFO | C78: RECORDACTION | D78: VARCHAR(32) | E78: YES | F78: 记录动作 | H78: VARCHAR | I78: 32
A79: 审计信息 | B79: AUDIT_INFO | C79: RECORDTARGET | D79: VARCHAR(200) | E79: YES | F79: 记录目标 | H79: VARCHAR | I79: 200
A80: 审计信息 | B80: AUDIT_INFO | C80: AUDITTIME | D80: VARCHAR(32) | E80: YES | F80: 修改时间 | H80: VARCHAR | I80: 32
A81: 审计信息 | B81: AUDIT_INFO | C81: INPUTORGID | D81: VARCHAR(32) | E81: YES | F81: 登记机构 | H81: VARCHAR | I81: 32
A82: 审计信息 | B82: AUDIT_INFO | C82: INPUTUSERID | D82: VARCHAR(32) | E82: YES | F82: 登记人 | H82: VARCHAR | I82: 32
... A92: 评估机构 | B92: APPRAISAL_AGENCY | C92: APPRAISALORGSTATUS | D92: VARCHAR(6) | E92: YES | F92: 评估机构状态 | H92: VARCHAR | I92: 6
A93: 评估机构 | B93: APPRAISAL_AGENCY | C93: REGISTERDATE | D93: DATETIME | E93: YES | F93: 机构成立日期 | H93: DATETIME
A94: 评估机构 | B94: APPRAISAL_AGENCY | C94: ASSETSTYPE | D94: VARCHAR(18) | E94: YES | F94: 可评估资产类型 | H94: VARCHAR | I94: 18
A95: 评估机构 | B95: APPRAISAL_AGENCY | C95: QUALIFYLEVEL | D95: VARCHAR(18) | E95: YES | F95: 执业资质等级 | H95: VARCHAR | I95: 18
A96: 评估机构 | B96: APPRAISAL_AGENCY | C96: ASSESSAREA | D96: VARCHAR(80) | E96: YES | F96: 可估价地域范围 | H96: VARCHAR | I96: 80
A97: 评估机构 | B97: APPRAISAL_AGENCY | C97: CERTNAME | D97: VARCHAR(80) | E97: YES | F97: 资质证书名称 | H97: VARCHAR | I97: 80
A98: 评估机构 | B98: APPRAISAL_AGENCY | C98: CERTID | D98: VARCHAR(32) | E98: YES | F98: 资质证书标号 | H98: VARCHAR | I98: 32
A99: 评估机构 | B99: APPRAISAL_AGENCY | C99: APPROVEDATE | D99: DATETIME | E99: YES | F99: 资质核准日期 | H99: DATETIME
A100: 评估机构 | B100: APPRAISAL_AGENCY | C100: APPROVEENDDATE | D100: DATETIME | E100: YES | F100: 资质到期日期 | H100: DATETIME
A101: 评估机构 | B101: APPRAISAL_AGENCY | C101: DEPARTMENTCARE | D101: VARCHAR(6) | E101: YES | F101: 行业主管部门是否年审 | H101: VARCHAR | I101: 6
A102: 评估机构 | B102: APPRAISAL_AGENCY | C102: INPUTUSER | D102: VARCHAR(80) | E102: YES | F102: 基本信息录入岗 | H102: VARCHAR | I102: 80
A103: 评估机构 | B103: APPRAISAL_AGENCY | C103: CONTINUETIME | D103: INT | E103: YES | F103: 连续执业时间 | H103: INT
A104: 评估机构 | B104: APPRAISAL_AGENCY | C104: BUSINESSSCOPE | D104: VARCHAR(500) | E104: YES | F104: 经营范围 | H104: VARCHAR | I104: 500
A105: 评估机构 | B105: APPRAISAL_AGENCY | C105: REGISTERCAPITAL | D105: DECIMAL(24,6) | E105: YES | F105: 注册资金 | H105: DECIMAL | I105: 24,6
A106: 评估机构 | B106: APPRAISAL_AGENCY | C106: LEGALREP | D106: VARCHAR(80) | E106: YES | F106: 法人代表 | H106: VARCHAR | I106: 80
...

Sheet Sheet2

Sheet 新增字段查找
K2: EQ
S3: 列名 | T3: 长度 | V3: 注释 | W3: 码值 | X3: 备注 | AA3: 备注
C4: 开始票据区间 | D4: BILLRANGESTART | E4: varchar(20) | F4: YES | G4: 开始票据区间 | N4: =O4&P4&Q4 | O4: =IFERROR(VLOOKUP( | P4: V4 | Q4: ,新增字段查找!C4:I500,2,FALSE),"") | S4: =IFERROR(VLOOKUP(V4,新增字段查找!C4:I500,2,FALSE),"") | T4: =IFERROR(VLOOKUP(V4,新增字段查找!C4:I500,3,FALSE),"") | U4: YES | V4: 客户名称 | W4: =IFERROR(VLOOKUP(V4,新增字段查找!C4:I500,6,FALSE),"") | X4: =IFERROR(VLOOKUP(V4,新增字段查找!C4:I500,7,FALSE),"") | AA4: =IFERROR(VLOOKUP(P4,新增字段查找!C4:I37,7,FALSE),"")
C5: 截止票据区间 | D5: BILLRANGEEND | E5: varchar(20) | F5: YES | G5: 截止票据区间 | M5: =VLOOKUP("YES",F4:G37,2,FALSE) | N5: =O5&P5&Q5 | O5: =IFERROR(VLOOKUP( | P5: V5 | Q5: ,新增字段查找!C4:I500,2,FALSE),"") | S5: =IFERROR(VLOOKUP(V5,新增字段查找!C4:I500,2,FALSE),"") | T5: =IFERROR(VLOOKUP(V5,新增字段查找!C4:I500,3,FALSE),"") | U5: YES | V5: 客户号 | W5: =IFERROR(VLOOKUP(V5,新增字段查找!C4:I500,6,FALSE),"") | X5: =IFERROR(VLOOKUP(V5,新增字段查找!C4:I500,7,FALSE),"") | AA5: =IFERROR(VLOOKUP(P5,新增字段查找!C4:I37,7,FALSE),"")
C6: 冻结止付编号 | D6: FRZNO | E6: varchar(32) | F6: YES | G6: 冻结止付编号 | N6: =O6&P6&Q6 | O6: =IFERROR(VLOOKUP( | P6: V6 | Q6: ,新增字段查找!C4:I500,2,FALSE),"") | S6: =IFERROR(VLOOKUP(V6,新增字段查找!C4:I500,2,FALSE),"") | T6: =IFERROR(VLOOKUP(V6,新增字段查找!C4:I500,3,FALSE),"") | U6: YES | V6: 项目立项批文文号 | W6: =IFERROR(VLOOKUP(V6,新增字段查找!C4:I500,6,FALSE),"") | X6: =IFERROR(VLOOKUP(V6,新增字段查找!C4:I500,7,FALSE),"") | AA6: =IFERROR(VLOOKUP(P6,新增字段查找!C4:I37,7,FALSE),"")
C7: 存单介质/票据介质 | D7: BILLMEDIUM | E7: varchar(6) | F7: YES | G7: 存单介质/票据介质 | I7: 1-纸质、2-电子 | N7: =O7&P7&Q7 | O7: =IFERROR(VLOOKUP( | P7: V7 | Q7: ,新增字段查找!C4:I500,2,FALSE),"") | S7: =IFERROR(VLOOKUP(V7,新增字段查找!C4:I500,2,FALSE),"") | T7: =IFERROR(VLOOKUP(V7,新增字段查找!C4:I500,3,FALSE),"") | U7: YES | V7: 收费权确认文号 | W7: =IFERROR(VLOOKUP(V7,新增字段查找!C4:I500,6,FALSE),"") | X7: =IFERROR(VLOOKUP(V7,新增字段查找!C4:I500,7,FALSE),"") | AA7: =IFERROR(VLOOKUP(P7,新增字段查找!C4:I37,7,FALSE),"")
C8: 质押物登记情况 | D8: REGISTERINFO | E8: varchar(500) | F8: YES | G8: 质押物登记情况 | N8: =O8&P8&Q8 | O8: =IFERROR(VLOOKUP( | P8: V8 | Q8: ,新增字段查找!C4:I500,2,FALSE),"") | S8: =IFERROR(VLOOKUP(V8,新增字段查找!C4:I500,2,FALSE),"") | T8: =IFERROR(VLOOKUP(V8,新增字段查找!C4:I500,3,FALSE),"") | U8: YES | V8: 可质押批复文号 | W8: =IFERROR(VLOOKUP(V8,新增字段查找!C4:I500,6,FALSE),"") | X8: =IFERROR(VLOOKUP(V8,新增字段查找!C4:I500,7,FALSE),"") | AA8: =IFERROR(VLOOKUP(P8,新增字段查找!C4:I37,7,FALSE),"")
C9: 冻结状态/冻结类型 | D9: FRZSTATUS | E9: varchar(6) | F9: YES | G9: 冻结状态/冻结类型 | I9: 冻结类型：1.冻结 2.未冻结 | N9: =O9&P9&Q9 | O9: =IFERROR(VLOOKUP( | P9: V9 | Q9: ,新增字段查找!C4:I500,2,FALSE),"") | S9: =IFERROR(VLOOKUP(V9,新增字段查找!C4:I500,2,FALSE),"") | T9: =IFERROR(VLOOKUP(V9,新增字段查找!C4:I500,3,FALSE),"") | U9: YES | V9: 币种 | W9: =IFERROR(VLOOKUP(V9,新增字段查找!C4:I500,6,FALSE),"") | X9: =IFERROR(VLOOKUP(V9,新增字段查找!C4:I500,7,FALSE),"") | AA9: =IFERROR(VLOOKUP(P9,新增字段查找!C4:I37,7,FALSE),"")
C10: 支出类型 | D10: PAYOUTTYPE | E10: varchar(6) | F10: YES | G10: 支出类型 | I10: 01 -密码 、 02- 证件 、03 -印鉴 | N10: =O10&P10&Q10 | O10: =IFERROR(VLOOKUP( | P10: V10 | Q10: ,新增字段查找!C4:I500,2,FALSE),"") | S10: =IFERROR(VLOOKUP(V10,新增字段查找!C4:I500,2,FALSE),"") | T10: =IFERROR(VLOOKUP(V10,新增字段查找!C4:I500,3,FALSE),"") | U10: YES | V10: 权利取得价值 | W10: =IFERROR(VLOOKUP(V10,新增字段查找!C4:I500,6,FALSE),"") | X10: =IFERROR(VLOOKUP(V10,新增字段查找!C4:I500,7,FALSE),"") | AA10: =IFERROR(VLOOKUP(P10,新增字段查找!C4:I37,7,FALSE),"")
C11: 出质人贷款卡号 | D11: LOANCARDNO | E11: varchar(32) | F11: YES | G11: 出质人贷款卡号 | N11: =O11&P11&Q11 | O11: =IFERROR(VLOOKUP( | P11: V11 | Q11: ,新增字段查找!C4:I500,2,FALSE),"") | S11: =IFERROR(VLOOKUP(V11,新增字段查找!C4:I500,2,FALSE),"") | T11: =IFERROR(VLOOKUP(V11,新增字段查找!C4:I500,3,FALSE),"") | U11: YES | V11: 是否在人行应收账款系统登记 | W11: =IFERROR(VLOOKUP(V11,新增字段查找!C4:I500,6,FALSE),"") | X11: =IFERROR(VLOOKUP(V11,新增字段查找!C4:I500,7,FALSE),"") | AA11: =IFERROR(VLOOKUP(P11,新增字段查找!C4:I37,7,FALSE),"")
C12: 款项 | D12: SELLAGRENO | E12: varchar(32) | F12: YES | G12: 款项 | N12: =O12&P12&Q12 | O12: =IFERROR(VLOOKUP( | P12: V12 | Q12: ,新增字段查找!C4:I500,2,FALSE),"") | S12: =IFERROR(VLOOKUP(V12,新增字段查找!C4:I500,2,FALSE),"") | T12: =IFERROR(VLOOKUP(V12,新增字段查找!C4:I500,3,FALSE),"") | U12: YES | V12: 贷款卡卡号/出质人贷款卡卡号 | W12: =IFERROR(VLOOKUP(V12,新增字段查找!C4:I500,6,FALSE),"") | X12: =IFERROR(VLOOKUP(V12,新增字段查找!C4:I500,7,FALSE),"") | AA12: =IFERROR(VLOOKUP(P12,新增字段查找!C4:I37,7,FALSE),"")
C13: 预计变现值 | D13: REALIZATIONVALUE | E13: decimal(24,6) | F13: YES | G13: 预计变现值 | K13: =I14 | N13: =O13&P13&Q13 | O13: =IFERROR(VLOOKUP( | P13: V13 | Q13: ,新增字段查找!C4:I500,2,FALSE),"") | S13: =IFERROR(VLOOKUP(V13,新增字段查找!C4:I500,2,FALSE),"") | T13: =IFERROR(VLOOKUP(V13,新增字段查找!C4:I500,3,FALSE),"") | U13: YES | V13: 是否需要约定回款路径 | W13: =IFERROR(VLOOKUP(V13,新增字段查找!C4:I500,6,FALSE),"") | X13: =IFERROR(VLOOKUP(V13,新增字段查找!C4:I500,7,FALSE),"") | AA13: =IFERROR(VLOOKUP(P13,新增字段查找!C4:I37,7,FALSE),"")
C14: 预计变现成本 | D14: REALIZATIONCOST | E14: decimal(24,6) | F14: YES | G14: 预计变现成本 | N14: =O14&P14&Q14 | O14: =IFERROR(VLOOKUP( | P14: V14 | Q14: ,新增字段查找!C4:I500,2,FALSE),"") | S14: =IFERROR(VLOOKUP(V14,新增字段查找!C4:I500,2,FALSE),"") | T14: =IFERROR(VLOOKUP(V14,新增字段查找!C4:I500,3,FALSE),"") | U14: YES | V14: 帐龄 | W14: =IFERROR(VLOOKUP(V14,新增字段查找!C4:I500,6,FALSE),"") | X14: =IFERROR(VLOOKUP(V14,新增字段查找!C4:I500,7,FALSE),"") | AA14: =IFERROR(VLOOKUP(P14,新增字段查找!C4:I37,7,FALSE),"")
C15: 是否我行存单 | D15: ISOWNDEPOSIT | E15: varchar(6) | F15: YES | G15: 是否我行存单 | N15: =O15&P15&Q15 | O15: =IFERROR(VLOOKUP( | P15: V15 | Q15: ,新增字段查找!C4:I500,2,FALSE),"") | S15: =IFERROR(VLOOKUP(V15,新增字段查找!C4:I500,2,FALSE),"") | T15: =IFERROR(VLOOKUP(V15,新增字段查找!C4:I500,3,FALSE),"") | U15: YES | V15: 应收账款渠道类型 | W15: =IFERROR(VLOOKUP(V15,新增字段查找!C4:I500,6,FALSE),"") | X15: =IFERROR(VLOOKUP(V15,新增字段查找!C4:I500,7,FALSE),"") | AA15: =IFERROR(VLOOKUP(P15,新增字段查找!C4:I37,7,FALSE),"")
C16: 保证金比例/持有股权比例 | D16: MARGINRATIO | E16: decimal(18,8) | F16: YES | G16: 保证金比例/持有股权比例 | N16: =O16&P16&Q16 | O16: =IFERROR(VLOOKUP( | P16: V16 | Q16: ,新增字段查找!C4:I500,2,FALSE),"") | S16: =IFERROR(VLOOKUP(V16,新增字段查找!C4:I500,2,FALSE),"") | T16: =IFERROR(VLOOKUP(V16,新增字段查找!C4:I500,3,FALSE),"") | U16: YES | V16: 预计变现值 | W16: =IFERROR(VLOOKUP(V16,新增字段查找!C4:I500,6,FALSE),"") | X16: =IFERROR(VLOOKUP(V16,新增字段查找!C4:I500,7,FALSE),"") | AA16: =IFERROR(VLOOKUP(P16,新增字段查找!C4:I37,7,FALSE),"")
C17: 其他特别约定 | D17: OTHERAGREEMENTS | E17: varchar(200) | F17: YES | G17: 其他特别约定 | N17: =O17&P17&Q17 | O17: =IFERROR(VLOOKUP( | P17: V17 | Q17: ,新增字段查找!C4:I500,2,FALSE),"") | S17: =IFERROR(VLOOKUP(V17,新增字段查找!C4:I500,2,FALSE),"") | T17: =IFERROR(VLOOKUP(V17,新增字段查找!C4:I500,3,FALSE),"") | U17: YES | V17: 预计变现成本 | W17: =IFERROR(VLOOKUP(V17,新增字段查找!C4:I500,6,FALSE),"") | X17: =IFERROR(VLOOKUP(V17,新增字段查找!C4:I500,7,FALSE),"") | AA17: =IFERROR(VLOOKUP(P17,新增字段查找!C4:I37,7,FALSE),"")
C18: 核保时间 | D18: UNDERWRITINGDATE | E18: datetime | F18: YES | G18: 核保时间 | N18: =O18&P18&Q18 | O18: =IFERROR(VLOOKUP( | P18: V18 | Q18: ,新增字段查找!C4:I500,2,FALSE),"") | S18: =IFERROR(VLOOKUP(V18,新增字段查找!C4:I500,2,FALSE),"") | T18: =IFERROR(VLOOKUP(V18,新增字段查找!C4:I500,3,FALSE),"") | U18: YES | V18: 权证号码 | W18: =IFERROR(VLOOKUP(V18,新增字段查找!C4:I500,6,FALSE),"") | X18: =IFERROR(VLOOKUP(V18,新增字段查找!C4:I500,7,FALSE),"") | AA18: =IFERROR(VLOOKUP(P18,新增字段查找!C4:I37,7,FALSE),"")
C19: 核保人 | D19: UNDERWRITER | E19: varchar(32) | F19: YES | G19: 核保人 | N19: =O19&P19&Q19 | O19: =IFERROR(VLOOKUP( | P19: V19 | Q19: ,新增字段查找!C4:I500,2,FALSE),"") | S19: =IFERROR(VLOOKUP(V19,新增字段查找!C4:I500,2,FALSE),"") | T19: =IFERROR(VLOOKUP(V19,新增字段查找!C4:I500,3,FALSE),"") | U19: YES | V19: 买方客户号 | W19: =IFERROR(VLOOKUP(V19,新增字段查找!C4:I500,6,FALSE),"") | X19: =IFERROR(VLOOKUP(V19,新增字段查找!C4:I500,7,FALSE),"") | AA19: =IFERROR(VLOOKUP(P19,新增字段查找!C4:I37,7,FALSE),"")
C20: 接待人姓名 | D20: RECEPTIONISTNAME | E20: varchar(32) | F20: YES | G20: 接待人姓名 | N20: =O20&P20&Q20 | O20: =IFERROR(VLOOKUP( | P20: V20 | Q20: ,新增字段查找!C4:I500,2,FALSE),"") | S20: =IFERROR(VLOOKUP(V20,新增字段查找!C4:I500,2,FALSE),"") | T20: =IFERROR(VLOOKUP(V20,新增字段查找!C4:I500,3,FALSE),"") | U20: YES | V20: MDM核心企业编码 | W20: =IFERROR(VLOOKUP(V20,新增字段查找!C4:I500,6,FALSE),"") | X20: =IFERROR(VLOOKUP(V20,新增字段查找!C4:I500,7,FALSE),"") | AA20: =IFERROR(VLOOKUP(P20,新增字段查找!C4:I37,7,FALSE),"")
C21: 接待人职务 | D21: RECEPTIONISTPOSITION | E21: varchar(32) | F21: YES | G21: 接待人职务 | N21: =O21&P21&Q21 | O21: =IFERROR(VLOOKUP( | P21: V21 | Q21: ,新增字段查找!C4:I500,2,FALSE),"") | S21: =IFERROR(VLOOKUP(V21,新增字段查找!C4:I500,2,FALSE),"") | T21: =IFERROR(VLOOKUP(V21,新增字段查找!C4:I500,3,FALSE),"") | U21: YES | V21: 卖方客户号 | W21: =IFERROR(VLOOKUP(V21,新增字段查找!C4:I500,6,FALSE),"") | X21: =IFERROR(VLOOKUP(V21,新增字段查找!C4:I500,7,FALSE),"") | AA21: =IFERROR(VLOOKUP(P21,新增字段查找!C4:I37,7,FALSE),"")
C22: 担保意见 | D22: GUARANTEEOPINION | E22: varchar(200) | F22: YES | G22: 担保意见 | N22: =O22&P22&Q22 | O22: =IFERROR(VLOOKUP( | P22: V22 | Q22: ,新增字段查找!C4:I500,2,FALSE),"") | S22: =IFERROR(VLOOKUP(V22,新增字段查找!C4:I500,2,FALSE),"") | T22: =IFERROR(VLOOKUP(V22,新增字段查找!C4:I500,3,FALSE),"") | U22: YES | V22: 应收账款已结算金额及其他扣除项 | W22: =IFERROR(VLOOKUP(V22,新增字段查找!C4:I500,6,FALSE),"") | X22: =IFERROR(VLOOKUP(V22,新增字段查找!C4:I500,7,FALSE),"") | AA22: =IFERROR(VLOOKUP(P22,新增字段查找!C4:I37,7,FALSE),"")
C23: 债券利率类型 | D23: RATETYPE | E23: varchar(6) | F23: YES | G23: 债券利率类型 | N23: =O23&P23&Q23 | O23: =IFERROR(VLOOKUP( | P23: V23 | Q23: ,新增字段查找!C4:I500,2,FALSE),"") | S23: =IFERROR(VLOOKUP(V23,新增字段查找!C4:I500,2,FALSE),"") | T23: =IFERROR(VLOOKUP(V23,新增字段查找!C4:I500,3,FALSE),"") | U23: YES | V23: 应收账款转让申请号 | W23: =IFERROR(VLOOKUP(V23,新增字段查找!C4:I500,6,FALSE),"") | X23: =IFERROR(VLOOKUP(V23,新增字段查找!C4:I500,7,FALSE),"") | AA23: =IFERROR(VLOOKUP(P23,新增字段查找!C4:I37,7,FALSE),"")
C24: 是否需要办理止付 | D24: ISSTOPPAYMENTREQUIRED | E24: varchar(6) | F24: YES | G24: 是否需要办理止付 | N24: =O24&P24&Q24 | O24: =IFERROR(VLOOKUP( | P24: V24 | Q24: ,新增字段查找!C4:I500,2,FALSE),"") | S24: =IFERROR(VLOOKUP(V24,新增字段查找!C4:I500,2,FALSE),"") | T24: =IFERROR(VLOOKUP(V24,新增字段查找!C4:I500,3,FALSE),"") | U24: YES | V24: 应收账款转让申请时间 | W24: =IFERROR(VLOOKUP(V24,新增字段查找!C4:I500,6,FALSE),"") | X24: =IFERROR(VLOOKUP(V24,新增字段查找!C4:I500,7,FALSE),"") | AA24: =IFERROR(VLOOKUP(P24,新增字段查找!C4:I37,7,FALSE),"")
C25: 付款行名称 | D25: PAYINGBANKNAME | E25: varchar(32) | F25: YES | G25: 付款行名称 | N25: =O25&P25&Q25 | O25: =IFERROR(VLOOKUP( | P25: V25 | Q25: ,新增字段查找!C4:I500,2,FALSE),"") | S25: =IFERROR(VLOOKUP(V25,新增字段查找!C4:I500,2,FALSE),"") | T25: =IFERROR(VLOOKUP(V25,新增字段查找!C4:I500,3,FALSE),"") | U25: YES | V25: 融资卖方额度号 | W25: =IFERROR(VLOOKUP(V25,新增字段查找!C4:I500,6,FALSE),"") | X25: =IFERROR(VLOOKUP(V25,新增字段查找!C4:I500,7,FALSE),"") | AA25: =IFERROR(VLOOKUP(P25,新增字段查找!C4:I37,7,FALSE),"")
C26: 是否具有真实的商品交易背景 | D26: HASREALTRADEBACKGROUND | E26: varchar(6) | F26: YES | G26: 是否具有真实的商品交易背景 | N26: =O26&P26&Q26 | O26: =IFERROR(VLOOKUP( | P26: V26 | Q26: ,新增字段查找!C4:I500,2,FALSE),"") | S26: =IFERROR(VLOOKUP(V26,新增字段查找!C4:I500,2,FALSE),"") | T26: =IFERROR(VLOOKUP(V26,新增字段查找!C4:I500,3,FALSE),"") | U26: YES | V26: 单笔/池 | W26: =IFERROR(VLOOKUP(V26,新增字段查找!C4:I500,6,FALSE),"") | X26: =IFERROR(VLOOKUP(V26,新增字段查找!C4:I500,7,FALSE),"") | AA26: =IFERROR(VLOOKUP(P26,新增字段查找!C4:I37,7,FALSE),"")
C27: 托收收款保证金账号 | D27: MARGINACCOUNT | E27: varchar(32) | F27: YES | G27: 托收收款保证金账号 | N27: =O27&P27&Q27 | O27: =IFERROR(VLOOKUP( | P27: V27 | Q27: ,新增字段查找!C4:I500,2,FALSE),"") | S27: =IFERROR(VLOOKUP(V27,新增字段查找!C4:I500,2,FALSE),"") | T27: =IFERROR(VLOOKUP(V27,新增字段查找!C4:I500,3,FALSE),"") | U27: YES | V27: 池编号 | W27: =IFERROR(VLOOKUP(V27,新增字段查找!C4:I500,6,FALSE),"") | X27: =IFERROR(VLOOKUP(V27,新增字段查找!C4:I500,7,FALSE),"") | AA27: =IFERROR(VLOOKUP(P27,新增字段查找!C4:I37,7,FALSE),"")
C28: 上市公司是否盈利 | D28: ISPROFITABLE | E28: varchar(6) | F28: YES | G28: 上市公司是否盈利 | N28: =O28&P28&Q28 | O28: =IFERROR(VLOOKUP( | P28: V28 | Q28: ,新增字段查找!C4:I500,2,FALSE),"") | S28: =IFERROR(VLOOKUP(V28,新增字段查找!C4:I500,2,FALSE),"") | T28: =IFERROR(VLOOKUP(V28,新增字段查找!C4:I500,3,FALSE),"") | U28: YES | V28: 期限（天） | W28: =IFERROR(VLOOKUP(V28,新增字段查找!C4:I500,6,FALSE),"") | X28: =IFERROR(VLOOKUP(V28,新增字段查找!C4:I500,7,FALSE),"") | AA28: =IFERROR(VLOOKUP(P28,新增字段查找!C4:I37,7,FALSE),"")
C29: 质押基金份额占总额 | D29: SHARERATIO | E29: decimal(18,8) | F29: YES | G29: 质押基金份额占总额 | N29: =O29&P29&Q29 | O29: =IFERROR(VLOOKUP( | P29: V29 | Q29: ,新增字段查找!C4:I500,2,FALSE),"") | S29: =IFERROR(VLOOKUP(V29,新增字段查找!C4:I500,2,FALSE),"") | T29: =IFERROR(VLOOKUP(V29,新增字段查找!C4:I500,3,FALSE),"") | U29: YES | V29: 具体单位名称 | W29: =IFERROR(VLOOKUP(V29,新增字段查找!C4:I500,6,FALSE),"") | X29: =IFERROR(VLOOKUP(V29,新增字段查找!C4:I500,7,FALSE),"") | AA29: =IFERROR(VLOOKUP(P29,新增字段查找!C4:I37,7,FALSE),"")
C30: 保单现金价值确认部门 | D30: CONFIRMDEPARTMENT | E30: varchar(32) | F30: YES | G30: 保单现金价值确认部门 | N30: =O30&P30&Q30 | O30: =IFERROR(VLOOKUP( | P30: V30 | Q30: ,新增字段查找!C4:I500,2,FALSE),"") | S30: =IFERROR(VLOOKUP(V30,新增字段查找!C4:I500,2,FALSE),"") | T30: =IFERROR(VLOOKUP(V30,新增字段查找!C4:I500,3,FALSE),"") | U30: YES | V30: 发票完整性 | W30: =IFERROR(VLOOKUP(V30,新增字段查找!C4:I500,6,FALSE),"") | X30: =IFERROR(VLOOKUP(V30,新增字段查找!C4:I500,7,FALSE),"") | AA30: =IFERROR(VLOOKUP(P30,新增字段查找!C4:I37,7,FALSE),"")
C31: 保险费交缴期限 | D31: PAYMENTPERIOD | E31: datetime | F31: YES | G31: 保险费交缴期限 | N31: =O31&P31&Q31 | O31: =IFERROR(VLOOKUP( | P31: V31 | Q31: ,新增字段查找!C4:I500,2,FALSE),"") | S31: =IFERROR(VLOOKUP(V31,新增字段查找!C4:I500,2,FALSE),"") | T31: =IFERROR(VLOOKUP(V31,新增字段查找!C4:I500,3,FALSE),"") | U31: YES | V31: 质押合同编号 | W31: =IFERROR(VLOOKUP(V31,新增字段查找!C4:I500,6,FALSE),"") | X31: =IFERROR(VLOOKUP(V31,新增字段查找!C4:I500,7,FALSE),"") | AA31: =IFERROR(VLOOKUP(P31,新增字段查找!C4:I37,7,FALSE),"")
C32: 理财质押范围 | D32: PLEDGESCOPE | E32: varchar(6) | F32: YES | G32: 理财质押范围 | I32: 01 本金、02 本金及未来收益 | N32: =O32&P32&Q32 | O32: =IFERROR(VLOOKUP( | P32: V32 | Q32: ,新增字段查找!C4:I500,2,FALSE),"") | S32: =IFERROR(VLOOKUP(V32,新增字段查找!C4:I500,2,FALSE),"") | T32: =IFERROR(VLOOKUP(V32,新增字段查找!C4:I500,3,FALSE),"") | U32: YES | V32: 合同名称 | W32: =IFERROR(VLOOKUP(V32,新增字段查找!C4:I500,6,FALSE),"") | X32: =IFERROR(VLOOKUP(V32,新增字段查找!C4:I500,7,FALSE),"") | AA32: =IFERROR(VLOOKUP(P32,新增字段查找!C4:I37,7,FALSE),"")
C33: 受益凭证 | D33: BENEFICIARYCERTIFICATE | E33: varchar(50) | F33: YES | G33: 受益凭证 | N33: =O33&P33&Q33 | O33: =IFERROR(VLOOKUP( | P33: V33 | Q33: ,新增字段查找!C4:I500,2,FALSE),"") | S33: =IFERROR(VLOOKUP(V33,新增字段查找!C4:I500,2,FALSE),"") | T33: =IFERROR(VLOOKUP(V33,新增字段查找!C4:I500,3,FALSE),"") | U33: YES | V33: 贷款企业法人代表姓名 | W33: =IFERROR(VLOOKUP(V33,新增字段查找!C4:I500,6,FALSE),"") | X33: =IFERROR(VLOOKUP(V33,新增字段查找!C4:I500,7,FALSE),"") | AA33: =IFERROR(VLOOKUP(P33,新增字段查找!C4:I37,7,FALSE),"")
C34: 是否保本型 | D34: ISPRINCIPALGUARANTEED | E34: varchar(6) | F34: YES | G34: 是否保本型 | N34: =O34&P34&Q34 | O34: =IFERROR(VLOOKUP( | P34: V34 | Q34: ,新增字段查找!C4:I500,2,FALSE),"") | S34: =IFERROR(VLOOKUP(V34,新增字段查找!C4:I500,2,FALSE),"") | T34: =IFERROR(VLOOKUP(V34,新增字段查找!C4:I500,3,FALSE),"") | U34: YES | V34: 纸质合同相对人名称 | W34: =IFERROR(VLOOKUP(V34,新增字段查找!C4:I500,6,FALSE),"") | X34: =IFERROR(VLOOKUP(V34,新增字段查找!C4:I500,7,FALSE),"") | AA34: =IFERROR(VLOOKUP(P34,新增字段查找!C4:I37,7,FALSE),"")
C35: 户主/姓名 | D35: ACCOUNTNAME | E35: varchar(32) | F35: YES | G35: 户主/姓名 | N35: =O35&P35&Q35 | O35: =IFERROR(VLOOKUP( | P35: V35 | Q35: ,新增字段查找!C4:I500,2,FALSE),"") | S35: =IFERROR(VLOOKUP(V35,新增字段查找!C4:I500,2,FALSE),"") | T35: =IFERROR(VLOOKUP(V35,新增字段查找!C4:I500,3,FALSE),"") | U35: YES | V35: 合同签订日期 | W35: =IFERROR(VLOOKUP(V35,新增字段查找!C4:I500,6,FALSE),"") | X35: =IFERROR(VLOOKUP(V35,新增字段查找!C4:I500,7,FALSE),"") | AA35: =IFERROR(VLOOKUP(P35,新增字段查找!C4:I37,7,FALSE),"")
C36: 权利凭证编号 | D36: RIGHTCERTNO | E36: varchar(32) | F36: YES | G36: 权利凭证编号 | V36: 客户名称
C37: 质押到期日期 | D37: PLEDGEEXPIRATIONDATE | E37: datetime | F37: YES | G37: 质押到期日期 | V37: 客户号
C38: 权利人贷款卡号 | D38: LOANCARDNO | E38: varchar(32) | F38: YES | G38: 权利人贷款卡号 | V38: 项目立项批文文号
C39: 设备现状 | D39: EQUIPSTATUS | E39: varchar(6) | F39: YES | G39: 设备现状 | I39: 01 -出租、02-占用、03-闲置、04-自用、05-其他 | V39: 收费权确认文号
C40: 抵押物说明 | D40: GUARANTYDESCRIPT | E40: varchar(800) | F40: YES | G40: 抵押物说明 | V40: 可质押批复文号
C41: 权证号 | D41: GUARANTYRIGHTID | E41: varchar(800) | F41: YES | G41: 权证号 | V41: 币种
...

Sheet 码值映射清单
B2: CODENO | C2: CODENAME | D2: ITEMNO | E2: ITEMNAME
B3: 码值：IndView
B4: IndView | C4: 个人客户详情视图 | D4: 010 | E4: 客户基本信息
B5: IndView | C5: 个人客户详情视图 | D5: 010010 | E5: 个人概况
B6: IndView | C6: 个人客户详情视图 | D6: 010015 | E6: 农户基本情况
B7: IndView | C7: 个人客户详情视图 | D7: 010020 | E7: 个人经营企业信息
B8: IndView | C8: 个人客户详情视图 | D8: 010030 | E8: 个人摊位厂房信息
B9: IndView | C9: 个人客户详情视图 | D9: 010040 | E9: 家庭成员信息
B10: IndView | C10: 个人客户详情视图 | D10: 010050 | E10: 个人学业履历
B11: IndView | C11: 个人客户详情视图 | D11: 010060 | E11: 个人工作履历
B12: IndView | C12: 个人客户详情视图 | D12: 010070 | E12: 客户涉诉信息
B13: IndView | C13: 个人客户详情视图 | D13: 010080 | E13: 客户大事记
B14: IndView | C14: 个人客户详情视图 | D14: 010090 | E14: 客户关联关系图谱
B15: IndView | C15: 个人客户详情视图 | D15: 010100 | E15: 客户担保关联图谱
... B46: IndView | C46: 个人客户详情视图 | D46: 110030 | E46: 客户引入记录
B47: 码值：文化水平
B48: 文化水平 | C48: 文化水平 | D48: 1 | E48: 初中
B49: 文化水平 | C49: 文化水平 | D49: 2 | E49: 高中
B50: 文化水平 | C50: 文化水平 | D50: 3 | E50: 大专
B51: 文化水平 | C51: 文化水平 | D51: 4 | E51: 本科及以上
B52: 码值：CountryRisk
B53: CountryRisk | C53: 国别风险 | D53: CountryRisk01 | E53: 中国
B54: CountryRisk | C54: 国别风险 | D54: CountryRisk02 | E54: 港澳台
B55: CountryRisk | C55: 国别风险 | D55: CountryRisk03 | E55: 欧洲
B56: CountryRisk | C56: 国别风险 | D56: CountryRisk04 | E56: 美国
B57: CountryRisk | C57: 国别风险 | D57: CountryRisk05 | E57: 日本
B58: CountryRisk | C58: 国别风险 | D58: CountryRisk06 | E58: 新加坡
B59: CountryRisk | C59: 国别风险 | D59: CountryRisk07 | E59: 东南亚其他国家
B60: CountryRisk | C60: 国别风险 | D60: CountryRisk08 | E60: 澳洲
B61: CountryRisk | C61: 国别风险 | D61: CountryRisk09 | E61: 北美
B62: CountryRisk | C62: 国别风险 | D62: CountryRisk10 | E62: 其他
B63: 码值：FamilyStatus
B64: FamilyStatus | C64: 居住状况 | D64: 1 | E64: 自置
B65: FamilyStatus | C65: 居住状况 | D65: 2 | E65: 按揭
B66: FamilyStatus | C66: 居住状况 | D66: 3 | E66: 亲属楼宇
B67: FamilyStatus | C67: 居住状况 | D67: 4 | E67: 集体宿舍
B68: FamilyStatus | C68: 居住状况 | D68: 5 | E68: 租房
B69: FamilyStatus | C69: 居住状况 | D69: 6 | E69: 共有住宅
B70: FamilyStatus | C70: 居住状况 | D70: 7 | E70: 其他
B71: FamilyStatus | C71: 居住状况 | D71: 9 | E71: 未知
...

Sheet audit_info
A1: =HYPERLINK("#表结构清单!A1","返回") | B1: 审计信息
B2: 表名 | C2: 列名 | D2: 字段类型 | E2: 是否为空 | F2: 字段注释 | G2: 码值 | H2: 备注 | I2: 修订人 | J2: 修订日期
A3: 审计信息 | B3: audit_info | C3: SERIALNO | D3: varchar(32) | E3: NO | F3: 流水号 | J3: 2023/01/12 | K3: =A3 | L3: =B3 | M3: =F3 | N3: =C3 | O3: =IFERROR(LEFT(D3,FIND("(",D3)-1),D3) | P3: =IFERROR(MID(D3,FIND("(",D3)+1,FIND(")",D3)-FIND("(",D3)-1),"")
A4: 审计信息 | B4: audit_info | C4: OPERATOR | D4: varchar(80) | E4: YES | F4: 操作人 | J4: 2023/01/12 | K4: =A4 | L4: =B4 | M4: =F4 | N4: =C4 | O4: =IFERROR(LEFT(D4,FIND("(",D4)-1),D4) | P4: =IFERROR(MID(D4,FIND("(",D4)+1,FIND(")",D4)-FIND("(",D4)-1),"")
A5: 审计信息 | B5: audit_info | C5: SERVERADDRESS | D5: varchar(80) | E5: YES | F5: 服务器地址 | J5: 2023/01/12 | K5: =A5 | L5: =B5 | M5: =F5 | N5: =C5 | O5: =IFERROR(LEFT(D5,FIND("(",D5)-1),D5) | P5: =IFERROR(MID(D5,FIND("(",D5)+1,FIND(")",D5)-FIND("(",D5)-1),"")
A6: 审计信息 | B6: audit_info | C6: CLIENTADDRESS | D6: varchar(80) | E6: YES | F6: 客户端地址 | J6: 2023/01/12 | K6: =A6 | L6: =B6 | M6: =F6 | N6: =C6 | O6: =IFERROR(LEFT(D6,FIND("(",D6)-1),D6) | P6: =IFERROR(MID(D6,FIND("(",D6)+1,FIND(")",D6)-FIND("(",D6)-1),"")
A7: 审计信息 | B7: audit_info | C7: APPLICATION | D7: varchar(200) | E7: YES | F7: 应用 | J7: 2023/01/12 | K7: =A7 | L7: =B7 | M7: =F7 | N7: =C7 | O7: =IFERROR(LEFT(D7,FIND("(",D7)-1),D7) | P7: =IFERROR(MID(D7,FIND("(",D7)+1,FIND(")",D7)-FIND("(",D7)-1),"")
A8: 审计信息 | B8: audit_info | C8: ADDITIONALINFO | D8: varchar(200) | E8: YES | F8: 附加信息 | J8: 2023/01/12 | K8: =A8 | L8: =B8 | M8: =F8 | N8: =C8 | O8: =IFERROR(LEFT(D8,FIND("(",D8)-1),D8) | P8: =IFERROR(MID(D8,FIND("(",D8)+1,FIND(")",D8)-FIND("(",D8)-1),"")
A9: 审计信息 | B9: audit_info | C9: RECORDTYPE | D9: varchar(32) | E9: YES | F9: 记录类型 | J9: 2023/01/12 | K9: =A9 | L9: =B9 | M9: =F9 | N9: =C9 | O9: =IFERROR(LEFT(D9,FIND("(",D9)-1),D9) | P9: =IFERROR(MID(D9,FIND("(",D9)+1,FIND(")",D9)-FIND("(",D9)-1),"")
A10: 审计信息 | B10: audit_info | C10: RECORDACTION | D10: varchar(32) | E10: YES | F10: 记录动作 | J10: 2023/01/12 | K10: =A10 | L10: =B10 | M10: =F10 | N10: =C10 | O10: =IFERROR(LEFT(D10,FIND("(",D10)-1),D10) | P10: =IFERROR(MID(D10,FIND("(",D10)+1,FIND(")",D10)-FIND("(",D10)-1),"")
A11: 审计信息 | B11: audit_info | C11: RECORDTARGET | D11: varchar(200) | E11: YES | F11: 记录目标 | J11: 2023/01/12 | K11: =A11 | L11: =B11 | M11: =F11 | N11: =C11 | O11: =IFERROR(LEFT(D11,FIND("(",D11)-1),D11) | P11: =IFERROR(MID(D11,FIND("(",D11)+1,FIND(")",D11)-FIND("(",D11)-1),"")
A12: 审计信息 | B12: audit_info | C12: AUDITTIME | D12: varchar(32) | E12: YES | F12: 修改时间 | J12: 2023/01/12 | K12: =A12 | L12: =B12 | M12: =F12 | N12: =C12 | O12: =IFERROR(LEFT(D12,FIND("(",D12)-1),D12) | P12: =IFERROR(MID(D12,FIND("(",D12)+1,FIND(")",D12)-FIND("(",D12)-1),"")
A13: 审计信息 | B13: audit_info | C13: INPUTORGID | D13: varchar(32) | E13: YES | F13: 登记机构 | J13: 2023/01/12 | K13: =A13 | L13: =B13 | M13: =F13 | N13: =C13 | O13: =IFERROR(LEFT(D13,FIND("(",D13)-1),D13) | P13: =IFERROR(MID(D13,FIND("(",D13)+1,FIND(")",D13)-FIND("(",D13)-1),"")
A14: 审计信息 | B14: audit_info | C14: INPUTUSERID | D14: varchar(32) | E14: YES | F14: 登记人 | J14: 2023/01/12 | K14: =A14 | L14: =B14 | M14: =F14 | N14: =C14 | O14: =IFERROR(LEFT(D14,FIND("(",D14)-1),D14) | P14: =IFERROR(MID(D14,FIND("(",D14)+1,FIND(")",D14)-FIND("(",D14)-1),"")
... A19: 审计信息 | B19: audit_info | C19: AUDITDATA | D19: varchar(2000) | E19: YES | F19: 审计数据 | J19: 2023/01/12 | K19: =A19 | L19: =B19 | M19: =F19 | N19: =C19 | O19: =IFERROR(LEFT(D19,FIND("(",D19)-1),D19) | P19: =IFERROR(MID(D19,FIND("(",D19)+1,FIND(")",D19)-FIND("(",D19)-1),"")

Sheet appraisal_agency
A1: =HYPERLINK("#表结构清单!A1","返回") | B1: 评估机构
A2: 评估机构 | B2: 表名 | C2: 列名 | D2: 字段类型 | E2: 是否为空 | F2: 字段注释 | G2: 码值 | H2: 备注 | I2: 修订人 | J2: 修订日期
A3: 评估机构 | B3: appraisal_agency | C3: APPRAISALORGID | D3: varchar(32) | E3: NO | F3: 评估机构编号 | J3: 2023/01/12 | K3: =A3 | L3: =B3 | M3: =F3 | N3: =C3 | O3: =IFERROR(LEFT(D3,FIND("(",D3)-1),D3) | P3: =IFERROR(MID(D3,FIND("(",D3)+1,FIND(")",D3)-FIND("(",D3)-1),"")
A4: 评估机构 | B4: appraisal_agency | C4: APPRAISALORGNAME | D4: varchar(80) | E4: YES | F4: 评估机构名称 | J4: 2023/01/12 | K4: =A4 | L4: =B4 | M4: =F4 | N4: =C4 | O4: =IFERROR(LEFT(D4,FIND("(",D4)-1),D4) | P4: =IFERROR(MID(D4,FIND("(",D4)+1,FIND(")",D4)-FIND("(",D4)-1),"")
A5: 评估机构 | B5: appraisal_agency | C5: APPRAISALORGTYPE | D5: varchar(18) | E5: YES | F5: 评估公司类型 02 特殊资产准入 03 特别准入;一次性) | G5: =HYPERLINK("#码值映射清单!B9420","AppraisalOrgType") | J5: 2023/01/12 | K5: =A5 | L5: =B5 | M5: =F5 | N5: =C5 | O5: =IFERROR(LEFT(D5,FIND("(",D5)-1),D5) | P5: =IFERROR(MID(D5,FIND("(",D5)+1,FIND(")",D5)-FIND("(",D5)-1),"")
A6: 评估机构 | B6: appraisal_agency | C6: APPRAISALORGADDRESS | D6: varchar(500) | E6: YES | F6: 机构地址 | J6: 2023/01/12 | K6: =A6 | L6: =B6 | M6: =F6 | N6: =C6 | O6: =IFERROR(LEFT(D6,FIND("(",D6)-1),D6) | P6: =IFERROR(MID(D6,FIND("(",D6)+1,FIND(")",D6)-FIND("(",D6)-1),"")
A7: 评估机构 | B7: appraisal_agency | C7: APPRAISALORGSTATUS | D7: varchar(6) | E7: YES | F7: 评估机构状态 | G7: =HYPERLINK("#码值映射清单!B9986","AgencyStatus") | H7: 1-生效、2-失效 | J7: 45740 | K7: =A7 | L7: =B7 | M7: =F7 | N7: =C7 | O7: =IFERROR(LEFT(D7,FIND("(",D7)-1),D7) | P7: =IFERROR(MID(D7,FIND("(",D7)+1,FIND(")",D7)-FIND("(",D7)-1),"")
A8: 评估机构 | B8: appraisal_agency | C8: REGISTERDATE | D8: datetime | E8: YES | F8: 机构成立日期 | J8: 2023/01/12 | K8: =A8 | L8: =B8 | M8: =F8 | N8: =C8 | O8: =IFERROR(LEFT(D8,FIND("(",D8)-1),D8) | P8: =IFERROR(MID(D8,FIND("(",D8)+1,FIND(")",D8)-FIND("(",D8)-1),"")
A9: 评估机构 | B9: appraisal_agency | C9: ASSETSTYPE | D9: varchar(18) | E9: YES | F9: 可评估资产类型 | G9: =HYPERLINK("#码值映射清单!B8049","AssessAssetsType") | J9: 2023/01/12 | K9: =A9 | L9: =B9 | M9: =F9 | N9: =C9 | O9: =IFERROR(LEFT(D9,FIND("(",D9)-1),D9) | P9: =IFERROR(MID(D9,FIND("(",D9)+1,FIND(")",D9)-FIND("(",D9)-1),"")
A10: 评估机构 | B10: appraisal_agency | C10: QUALIFYLEVEL | D10: varchar(18) | E10: YES | F10: 执业资质等级 | J10: 2023/01/12 | K10: =A10 | L10: =B10 | M10: =F10 | N10: =C10 | O10: =IFERROR(LEFT(D10,FIND("(",D10)-1),D10) | P10: =IFERROR(MID(D10,FIND("(",D10)+1,FIND(")",D10)-FIND("(",D10)-1),"")
A11: 评估机构 | B11: appraisal_agency | C11: ASSESSAREA | D11: varchar(80) | E11: YES | F11: 可估价地域范围 | G11: =HYPERLINK("#码值映射清单!B9045","AssessArea") | J11: 2023/01/12 | K11: =A11 | L11: =B11 | M11: =F11 | N11: =C11 | O11: =IFERROR(LEFT(D11,FIND("(",D11)-1),D11) | P11: =IFERROR(MID(D11,FIND("(",D11)+1,FIND(")",D11)-FIND("(",D11)-1),"")
A12: 评估机构 | B12: appraisal_agency | C12: CERTNAME | D12: varchar(80) | E12: YES | F12: 资质证书名称 | J12: 2023/01/12 | K12: =A12 | L12: =B12 | M12: =F12 | N12: =C12 | O12: =IFERROR(LEFT(D12,FIND("(",D12)-1),D12) | P12: =IFERROR(MID(D12,FIND("(",D12)+1,FIND(")",D12)-FIND("(",D12)-1),"")
A13: 评估机构 | B13: appraisal_agency | C13: CERTID | D13: varchar(32) | E13: YES | F13: 资质证书标号 | J13: 2023/01/12 | K13: =A13 | L13: =B13 | M13: =F13 | N13: =C13 | O13: =IFERROR(LEFT(D13,FIND("(",D13)-1),D13) | P13: =IFERROR(MID(D13,FIND("(",D13)+1,FIND(")",D13)-FIND("(",D13)-1),"")
A14: 评估机构 | B14: appraisal_agency | C14: APPROVEDATE | D14: datetime | E14: YES | F14: 资质核准日期 | J14: 2023/01/12 | K14: =A14 | L14: =B14 | M14: =F14 | N14: =C14 | O14: =IFERROR(LEFT(D14,FIND("(",D14)-1),D14) | P14: =IFERROR(MID(D14,FIND("(",D14)+1,FIND(")",D14)-FIND("(",D14)-1),"")
A15: 评估机构 | B15: appraisal_agency | C15: APPROVEENDDATE | D15: datetime | E15: YES | F15: 资质到期日期 | J15: 2023/01/12 | K15: =A15 | L15: =B15 | M15: =F15 | N15: =C15 | O15: =IFERROR(LEFT(D15,FIND("(",D15)-1),D15) | P15: =IFERROR(MID(D15,FIND("(",D15)+1,FIND(")",D15)-FIND("(",D15)-1),"")
A16: 评估机构 | B16: appraisal_agency | C16: DEPARTMENTCARE | D16: varchar(6) | E16: YES | F16: 行业主管部门是否年审 | G16: =HYPERLINK("#码值映射清单!B5150","YesNo") | J16: 2023/01/12 | K16: =A16 | L16: =B16 | M16: =F16 | N16: =C16 | O16: =IFERROR(LEFT(D16,FIND("(",D16)-1),D16) | P16: =IFERROR(MID(D16,FIND("(",D16)+1,FIND(")",D16)-FIND("(",D16)-1),"")
A17: 评估机构 | B17: appraisal_agency | C17: INPUTUSER | D17: varchar(80) | E17: YES | F17: 基本信息录入岗 | J17: 2023/01/12 | K17: =A17 | L17: =B17 | M17: =F17 | N17: =C17 | O17: =IFERROR(LEFT(D17,FIND("(",D17)-1),D17) | P17: =IFERROR(MID(D17,FIND("(",D17)+1,FIND(")",D17)-FIND("(",D17)-1),"")
A18: 评估机构 | B18: appraisal_agency | C18: CONTINUETIME | D18: int | E18: YES | F18: 连续执业时间 | J18: 2023/01/12 | K18: =A18 | L18: =B18 | M18: =F18 | N18: =C18 | O18: =IFERROR(LEFT(D18,FIND("(",D18)-1),D18) | P18: =IFERROR(MID(D18,FIND("(",D18)+1,FIND(")",D18)-FIND("(",D18)-1),"")
A19: 评估机构 | B19: appraisal_agency | C19: BUSINESSSCOPE | D19: varchar(500) | E19: YES | F19: 经营范围 | J19: 2023/01/12 | K19: =A19 | L19: =B19 | M19: =F19 | N19: =C19 | O19: =IFERROR(LEFT(D19,FIND("(",D19)-1),D19) | P19: =IFERROR(MID(D19,FIND("(",D19)+1,FIND(")",D19)-FIND("(",D19)-1),"")
A20: 评估机构 | B20: appraisal_agency | C20: REGISTERCAPITAL | D20: decimal(24,6) | E20: YES | F20: 注册资金 | J20: 2023/01/12 | K20: =A20 | L20: =B20 | M20: =F20 | N20: =C20 | O20: =IFERROR(LEFT(D20,FIND("(",D20)-1),D20) | P20: =IFERROR(MID(D20,FIND("(",D20)+1,FIND(")",D20)-FIND("(",D20)-1),"")
A21: 评估机构 | B21: appraisal_agency | C21: LEGALREP | D21: varchar(80) | E21: YES | F21: 法人代表 | J21: 2023/01/12 | K21: =A21 | L21: =B21 | M21: =F21 | N21: =C21 | O21: =IFERROR(LEFT(D21,FIND("(",D21)-1),D21) | P21: =IFERROR(MID(D21,FIND("(",D21)+1,FIND(")",D21)-FIND("(",D21)-1),"")
A22: 评估机构 | B22: appraisal_agency | C22: ORGTELEPHONE | D22: varchar(18) | E22: YES | F22: 评估机构电话 | J22: 2023/01/12 | K22: =A22 | L22: =B22 | M22: =F22 | N22: =C22 | O22: =IFERROR(LEFT(D22,FIND("(",D22)-1),D22) | P22: =IFERROR(MID(D22,FIND("(",D22)+1,FIND(")",D22)-FIND("(",D22)-1),"")
A23: 评估机构 | B23: appraisal_agency | C23: ORGFAX | D23: varchar(18) | E23: YES | F23: 评估机构传真电话 | J23: 2023/01/12 | K23: =A23 | L23: =B23 | M23: =F23 | N23: =C23 | O23: =IFERROR(LEFT(D23,FIND("(",D23)-1),D23) | P23: =IFERROR(MID(D23,FIND("(",D23)+1,FIND(")",D23)-FIND("(",D23)-1),"")
A24: 评估机构 | B24: appraisal_agency | C24: ORGEMAIL | D24: varchar(32) | E24: YES | F24: 评估机构电子邮箱 | J24: 2023/01/12 | K24: =A24 | L24: =B24 | M24: =F24 | N24: =C24 | O24: =IFERROR(LEFT(D24,FIND("(",D24)-1),D24) | P24: =IFERROR(MID(D24,FIND("(",D24)+1,FIND(")",D24)-FIND("(",D24)-1),"")
A25: 评估机构 | B25: appraisal_agency | C25: APPRAISERNUM | D25: int | E25: YES | F25: 评估师数量 | J25: 2023/01/12 | K25: =A25 | L25: =B25 | M25: =F25 | N25: =C25 | O25: =IFERROR(LEFT(D25,FIND("(",D25)-1),D25) | P25: =IFERROR(MID(D25,FIND("(",D25)+1,FIND(")",D25)-FIND("(",D25)-1),"")
A26: 评估机构 | B26: appraisal_agency | C26: ISINBLACKLIST | D26: char(1) | E26: YES | F26: 是否黑名单 | G26: =HYPERLINK("#码值映射清单!B5150","YesNo") | J26: 2023/01/12 | K26: =A26 | L26: =B26 | M26: =F26 | N26: =C26 | O26: =IFERROR(LEFT(D26,FIND("(",D26)-1),D26) | P26: =IFERROR(MID(D26,FIND("(",D26)+1,FIND(")",D26)-FIND("(",D26)-1),"")
A27: 评估机构 | B27: appraisal_agency | C27: PARENTORGID | D27: varchar(80) | E27: YES | F27: 所属分行 | J27: 2023/01/12 | K27: =A27 | L27: =B27 | M27: =F27 | N27: =C27 | O27: =IFERROR(LEFT(D27,FIND("(",D27)-1),D27) | P27: =IFERROR(MID(D27,FIND("(",D27)+1,FIND(")",D27)-FIND("(",D27)-1),"")
A28: 评估机构 | B28: appraisal_agency | C28: APPRAISALCERTID | D28: varchar(32) | E28: YES | F28: 评估机构证件号码 | J28: 2023/01/12 | K28: =A28 | L28: =B28 | M28: =F28 | N28: =C28 | O28: =IFERROR(LEFT(D28,FIND("(",D28)-1),D28) | P28: =IFERROR(MID(D28,FIND("(",D28)+1,FIND(")",D28)-FIND("(",D28)-1),"")
A29: 评估机构 | B29: appraisal_agency | C29: APPRAISALCERTTYPE | D29: varchar(18) | E29: YES | F29: 评估机构证件类型 | G29: =HYPERLINK("#码值映射清单!B6810","EntCertType") | J29: 2023/01/12 | K29: =A29 | L29: =B29 | M29: =F29 | N29: =C29 | O29: =IFERROR(LEFT(D29,FIND("(",D29)-1),D29) | P29: =IFERROR(MID(D29,FIND("(",D29)+1,FIND(")",D29)-FIND("(",D29)-1),"")
A30: 评估机构 | B30: appraisal_agency | C30: RELACERTID | D30: varchar(32) | E30: YES | F30: 关联机构 | J30: 2023/01/12 | K30: =A30 | L30: =B30 | M30: =F30 | N30: =C30 | O30: =IFERROR(LEFT(D30,FIND("(",D30)-1),D30) | P30: =IFERROR(MID(D30,FIND("(",D30)+1,FIND(")",D30)-FIND("(",D30)-1),"")
A31: 评估机构 | B31: appraisal_agency | C31: TEMPSAVEFLAG | D31: char(1) | E31: YES | F31: 暂存标志 | J31: 2023/01/12 | K31: =A31 | L31: =B31 | M31: =F31 | N31: =C31 | O31: =IFERROR(LEFT(D31,FIND("(",D31)-1),D31) | P31: =IFERROR(MID(D31,FIND("(",D31)+1,FIND(")",D31)-FIND("(",D31)-1),"")
A32: 评估机构 | B32: appraisal_agency | C32: ISINALERTLIST | D32: char(1) | E32: YES | F32: 警示标识 | J32: 2023/01/12 | K32: =A32 | L32: =B32 | M32: =F32 | N32: =C32 | O32: =IFERROR(LEFT(D32,FIND("(",D32)-1),D32) | P32: =IFERROR(MID(D32,FIND("(",D32)+1,FIND(")",D32)-FIND("(",D32)-1),"")
A33: 评估机构 | B33: appraisal_agency | C33: INPUTUSERID | D33: varchar(32) | E33: YES | F33: 登记人 | J33: 2023/01/12 | K33: =A33 | L33: =B33 | M33: =F33 | N33: =C33 | O33: =IFERROR(LEFT(D33,FIND("(",D33)-1),D33) | P33: =IFERROR(MID(D33,FIND("(",D33)+1,FIND(")",D33)-FIND("(",D33)-1),"")
A34: 评估机构 | B34: appraisal_agency | C34: INPUTORGID | D34: varchar(32) | E34: YES | F34: 登记机构 | J34: 2023/01/12 | K34: =A34 | L34: =B34 | M34: =F34 | N34: =C34 | O34: =IFERROR(LEFT(D34,FIND("(",D34)-1),D34) | P34: =IFERROR(MID(D34,FIND("(",D34)+1,FIND(")",D34)-FIND("(",D34)-1),"")
A35: 评估机构 | B35: appraisal_agency | C35: INPUTDATE | D35: datetime | E35: YES | F35: 登记日期 | J35: 2023/01/12 | K35: =A35 | L35: =B35 | M35: =F35 | N35: =C35 | O35: =IFERROR(LEFT(D35,FIND("(",D35)-1),D35) | P35: =IFERROR(MID(D35,FIND("(",D35)+1,FIND(")",D35)-FIND("(",D35)-1),"")
A36: 评估机构 | B36: appraisal_agency | C36: UPDATEUSERID | D36: varchar(32) | E36: YES | F36: 更新人 | J36: 2023/01/12 | K36: =A36 | L36: =B36 | M36: =F36 | N36: =C36 | O36: =IFERROR(LEFT(D36,FIND("(",D36)-1),D36) | P36: =IFERROR(MID(D36,FIND("(",D36)+1,FIND(")",D36)-FIND("(",D36)-1),"")
A37: 评估机构 | B37: appraisal_agency | C37: UPDATEORGID | D37: varchar(32) | E37: YES | F37: 更新机构 | J37: 2023/01/12 | K37: =A37 | L37: =B37 | M37: =F37 | N37: =C37 | O37: =IFERROR(LEFT(D37,FIND("(",D37)-1),D37) | P37: =IFERROR(MID(D37,FIND("(",D37)+1,FIND(")",D37)-FIND("(",D37)-1),"")
A38: 评估机构 | B38: appraisal_agency | C38: UPDATEDATE | D38: datetime | E38: YES | F38: 更新日期 | J38: 2023/01/12 | K38: =A38 | L38: =B38 | M38: =F38 | N38: =C38 | O38: =IFERROR(LEFT(D38,FIND("(",D38)-1),D38) | P38: =IFERROR(MID(D38,FIND("(",D38)+1,FIND(")",D38)-FIND("(",D38)-1),"")
A39: 评估机构 | B39: appraisal_agency | C39: REMARK | D39: varchar(1000) | E39: YES | F39: 备注 | J39: 2023/01/12 | K39: =A39 | L39: =B39 | M39: =F39 | N39: =C39 | O39: =IFERROR(LEFT(D39,FIND("(",D39)-1),D39) | P39: =IFERROR(MID(D39,FIND("(",D39)+1,FIND(")",D39)-FIND("(",D39)-1),"")
A40: 评估机构 | B40: appraisal_agency | C40: CORPORGID | D40: varchar(32) | E40: YES | F40: 法人机构编号 | J40: 2023/01/12 | K40: =A40 | L40: =B40 | M40: =F40 | N40: =C40 | O40: =IFERROR(LEFT(D40,FIND("(",D40)-1),D40) | P40: =IFERROR(MID(D40,FIND("(",D40)+1,FIND(")",D40)-FIND("(",D40)-1),"")
...

Sheet appraisal_agency_apply
A1: =HYPERLINK("#表结构清单!A1","返回") | B1: 评估机构申请信息表
B2: 表名 | C2: 列名 | D2: 字段类型 | E2: 是否为空 | F2: 字段注释 | G2: 码值 | H2: 备注 | I2: 修订人 | J2: 修订日期
B3: appraisal_agency_apply | C3: EVENTSERIALNO | D3: varchar(32) | E3: NO | F3: 评估机构事件编号 | J3: 2023/01/12
B4: appraisal_agency_apply | C4: APPLYTYPE | D4: varchar(32) | E4: YES | F4: 申请类型 | G4: =HYPERLINK("#码值映射清单!B7547","AppraisalFlowType2") | J4: 2023/01/12
B5: appraisal_agency_apply | C5: APPROVESTATUS | D5: varchar(32) | E5: YES | F5: 申请状态 | G5: =HYPERLINK("#码值映射清单!B1429","ApproveStatus") | J5: 2023/01/12
B6: appraisal_agency_apply | C6: FLOWTYPE | D6: varchar(32) | E6: YES | F6: 流程类型 | J6: 2023/01/12
B7: appraisal_agency_apply | C7: INPUTUSERID | D7: varchar(32) | E7: YES | F7: 登记人 | J7: 2023/01/12
B8: appraisal_agency_apply | C8: INPUTORGID | D8: varchar(32) | E8: YES | F8: 登记机构 | J8: 2023/01/12
B9: appraisal_agency_apply | C9: INPUTDATE | D9: datetime | E9: YES | F9: 登记日期 | J9: 2023/01/12
B10: appraisal_agency_apply | C10: UPDATEUSERID | D10: varchar(32) | E10: YES | F10: 更新人 | J10: 2023/01/12
B11: appraisal_agency_apply | C11: UPDATEORGID | D11: varchar(32) | E11: YES | F11: 更新机构 | J11: 2023/01/12
B12: appraisal_agency_apply | C12: UPDATEDATE | D12: datetime | E12: YES | F12: 更新日期 | J12: 2023/01/12
B13: appraisal_agency_apply | C13: REMARK | D13: varchar(500) | E13: YES | F13: 备注 | G13: =HYPERLINK("#码值映射清单!B5361","AppraisalFlowType") | J13: 2023/01/12
B14: appraisal_agency_apply | C14: CORPORGID | D14: varchar(32) | E14: YES | F14: 法人机构编号 | J14: 2023/01/12

Sheet appraisal_agency_appraise
A1: =HYPERLINK("#表结构清单!A1","返回") | B1: 评价调查信息管理
B2: 表名 | C2: 列名 | D2: 字段类型 | E2: 是否为空 | F2: 字段注释 | G2: 码值 | H2: 备注 | I2: 修订人 | J2: 修订日期
B3: appraisal_agency_appraise | C3: EVENTSERIALNO | D3: varchar(32) | E3: NO | F3: 评估机构事件编号 | J3: 2023/01/12
B4: appraisal_agency_appraise | C4: EVENTTYPE | D4: varchar(32) | E4: YES | F4: 事件类型 | J4: 2023/01/12
B5: appraisal_agency_appraise | C5: CLRID | D5: varchar(32) | E5: YES | F5: 抵质押品编号 | J5: 2023/01/12
B6: appraisal_agency_appraise | C6: BUSINESSTYPE | D6: varchar(18) | E6: YES | F6: 委托业务类型 | J6: 2023/01/12
B7: appraisal_agency_appraise | C7: PERSONFEEDBACK | D7: varchar(1000) | E7: YES | F7: 人员反馈事项 | J7: 2023/01/12
B8: appraisal_agency_appraise | C8: OTHERFEEDBACK | D8: varchar(1000) | E8: YES | F8: 其他反馈事项 | J8: 2023/01/12
B9: appraisal_agency_appraise | C9: FEEDMATTERADD | D9: varchar(1000) | E9: YES | F9: 人员反馈事项补充 | J9: 2023/01/12
B10: appraisal_agency_appraise | C10: APPRAISALDATE | D10: datetime | E10: YES | F10: 评价日期 | J10: 2023/01/12
B11: appraisal_agency_appraise | C11: INPUTUSERID | D11: varchar(32) | E11: YES | F11: 登记人 | J11: 2023/01/12
B12: appraisal_agency_appraise | C12: INPUTORGID | D12: varchar(32) | E12: YES | F12: 登记机构 | J12: 2023/01/12
B13: appraisal_agency_appraise | C13: INPUTDATE | D13: datetime | E13: YES | F13: 登记日期 | J13: 2023/01/12
B14: appraisal_agency_appraise | C14: UPDATEUSERID | D14: varchar(32) | E14: YES | F14: 更新人 | J14: 2023/01/12
... B19: appraisal_agency_appraise | C19: OPINION | D19: varchar(4000) | E19: YES | F19: 人员总体意见 | J19: 2023/01/12

Sheet appraisal_agency_cooperation
A1: =HYPERLINK("#表结构清单!A1","返回") | B1: 评估机构合作协议
B2: 表名 | C2: 列名 | D2: 字段类型 | E2: 是否为空 | F2: 字段注释 | G2: 码值 | H2: 备注 | I2: 修订人 | J2: 修订日期
B3: appraisal_agency_cooperation | C3: SERIALNO | D3: varchar(32) | E3: NO | F3: 流水号 | J3: 2023/01/12
B4: appraisal_agency_cooperation | C4: AGRMID | D4: varchar(32) | E4: YES | F4: 合作协议编号 | J4: 2023/01/12
B5: appraisal_agency_cooperation | C5: APPRAISALORGID | D5: varchar(32) | E5: YES | F5: 评估机构编号 | J5: 2023/01/12
B6: appraisal_agency_cooperation | C6: APPRAISALAPPLYNO | D6: varchar(32) | E6: YES | F6: 评估机构流程申请编号 | J6: 2023/01/12
B7: appraisal_agency_cooperation | C7: EFFECTIVEDATE | D7: datetime | E7: YES | F7: 生效日期 | J7: 2023/01/12
B8: appraisal_agency_cooperation | C8: EXPIRYDATE | D8: datetime | E8: YES | F8: 失效日期 | J8: 2023/01/12
B9: appraisal_agency_cooperation | C9: STATUS | D9: varchar(6) | E9: YES | F9: 状态 | J9: 2023/01/12
B10: appraisal_agency_cooperation | C10: BUSINESSTYPE | D10: varchar(18) | E10: YES | F10: 开展业务种类 | G10: =HYPERLINK("#码值映射清单!B8049","AssessAssetsType") | J10: 2023/01/12
B11: appraisal_agency_cooperation | C11: RISKDEPOSIT | D11: decimal(24,6) | E11: YES | F11: 风险保证金金额 | J11: 2023/01/12
B12: appraisal_agency_cooperation | C12: PAYDEPOSITDATE | D12: datetime | E12: YES | F12: 风险保证金交存日期 | J12: 2023/01/12
B13: appraisal_agency_cooperation | C13: RELIEVEDEPOSITDATES | D13: datetime | E13: YES | F13: 合作协议解除日期 | J13: 2023/01/12
B14: appraisal_agency_cooperation | C14: AGGREEMENTSIGNDATE | D14: datetime | E14: YES | F14: 合作协议书签署日期 | J14: 2023/01/12
B15: appraisal_agency_cooperation | C15: INPUTUSERID | D15: varchar(32) | E15: YES | F15: 登记人 | J15: 2023/01/12
B16: appraisal_agency_cooperation | C16: INPUTORGID | D16: varchar(32) | E16: YES | F16: 登记机构 | J16: 2023/01/12
B17: appraisal_agency_cooperation | C17: INPUTDATE | D17: datetime | E17: YES | F17: 登记日期 | J17: 2023/01/12
B18: appraisal_agency_cooperation | C18: UPDATEUSERID | D18: varchar(32) | E18: YES | F18: 更新人 | J18: 2023/01/12
B19: appraisal_agency_cooperation | C19: UPDATEORGID | D19: varchar(32) | E19: YES | F19: 更新机构 | J19: 2023/01/12
B20: appraisal_agency_cooperation | C20: UPDATEDATE | D20: datetime | E20: YES | F20: 更新日期 | J20: 2023/01/12
B21: appraisal_agency_cooperation | C21: REMARK | D21: varchar(1000) | E21: YES | F21: 备注 | J21: 2023/01/12
B22: appraisal_agency_cooperation | C22: CORPORGID | D22: varchar(32) | E22: YES | F22: 法人机构编号 | J22: 2023/01/12
B23: appraisal_agency_cooperation | C23: AGRMTXT | D23: varchar(4000) | E23: YES | F23: 合作协议文本 | J23: 2023/01/12

Sheet appraisal_agency_event
A1: =HYPERLINK("#表结构清单!A1","返回") | B1: 评估机构事件表
B2: 表名 | C2: 列名 | D2: 字段类型 | E2: 是否为空 | F2: 字段注释 | G2: 码值 | H2: 备注 | I2: 修订人 | J2: 修订日期
B3: appraisal_agency_event | C3: EVENTSERIALNO | D3: varchar(32) | E3: NO | F3: 评估机构事件编号 | J3: 2023/01/12
B4: appraisal_agency_event | C4: RELATIVESERIALNO | D4: varchar(32) | E4: YES | F4: 关联解除事件编号 | J4: 2023/01/12
B5: appraisal_agency_event | C5: EVENTTYPE | D5: varchar(32) | E5: YES | F5: 事件类型 | J5: 2023/01/12
B6: appraisal_agency_event | C6: EVENTSTATUS | D6: varchar(6) | E6: YES | F6: 事件状态 | J6: 2023/01/12
B7: appraisal_agency_event | C7: EVENTRULES | D7: varchar(6) | E7: YES | F7: 事件规则 | J7: 2023/01/12
B8: appraisal_agency_event | C8: EVENTREASON | D8: varchar(500) | E8: YES | F8: 事件说明 | J8: 2023/01/12
B9: appraisal_agency_event | C9: AFFIRMUSERID | D9: varchar(32) | E9: YES | F9: 认定人 | J9: 2023/01/12
B10: appraisal_agency_event | C10: AFFIRMORGID | D10: varchar(32) | E10: YES | F10: 认定机构 | J10: 2023/01/12
B11: appraisal_agency_event | C11: AFFIRMDATE | D11: datetime | E11: YES | F11: 认定时间 | J11: 2023/01/12
B12: appraisal_agency_event | C12: RELEASEUSERID | D12: varchar(32) | E12: YES | F12: 解除人 | J12: 2023/01/12
B13: appraisal_agency_event | C13: RELEASEORGID | D13: varchar(32) | E13: YES | F13: 解除机构 | J13: 2023/01/12
B14: appraisal_agency_event | C14: RELEASEDATE | D14: datetime | E14: YES | F14: 解除时间 | J14: 2023/01/12
... B23: appraisal_agency_event | C23: CORPORGID | D23: varchar(32) | E23: YES | F23: 法人机构编号 | J23: 2023/01/12

Sheet appraisal_agency_expenses
A1: =HYPERLINK("#表结构清单!A1","返回") | B1: 评估机构费用
B2: 表名 | C2: 列名 | D2: 字段类型 | E2: 是否为空 | F2: 字段注释 | G2: 码值 | H2: 备注 | I2: 修订人 | J2: 修订日期
B3: appraisal_agency_expenses | C3: SERIALNO | D3: varchar(32) | E3: NO | F3: 流水号 | J3: 2023/01/12
B4: appraisal_agency_expenses | C4: APPRAISALORGID | D4: varchar(32) | E4: NO | F4: 评估公司组织机构代码证 | J4: 2023/01/12
B5: appraisal_agency_expenses | C5: EVALRECORDID | D5: varchar(32) | E5: YES | F5: 评估记录流水号 | J5: 2023/01/12
B6: appraisal_agency_expenses | C6: FEENAME | D6: varchar(80) | E6: YES | F6: 费用名称 | J6: 2023/01/12
B7: appraisal_agency_expenses | C7: FEEACCOUNT | D7: decimal(24,6) | E7: YES | F7: 费用金额 | J7: 2023/01/12
B8: appraisal_agency_expenses | C8: OCCURDATE | D8: datetime | E8: NO | F8: 费用发生日期 | J8: 2023/01/12
B9: appraisal_agency_expenses | C9: INPUTUSERID | D9: varchar(32) | E9: YES | F9: 登记人 | J9: 2023/01/12
B10: appraisal_agency_expenses | C10: INPUTORGID | D10: varchar(32) | E10: YES | F10: 登记机构 | J10: 2023/01/12
B11: appraisal_agency_expenses | C11: INPUTDATE | D11: datetime | E11: YES | F11: 登记日期 | J11: 2023/01/12
B12: appraisal_agency_expenses | C12: UPDATEUSERID | D12: varchar(32) | E12: YES | F12: 更新人 | J12: 2023/01/12
B13: appraisal_agency_expenses | C13: UPDATEORGID | D13: varchar(32) | E13: YES | F13: 更新机构 | J13: 2023/01/12
B14: appraisal_agency_expenses | C14: UPDATEDATE | D14: datetime | E14: YES | F14: 更新日期 | J14: 2023/01/12
... B16: appraisal_agency_expenses | C16: CORPORGID | D16: varchar(32) | E16: YES | F16: 法人机构编号 | J16: 2023/01/12

Sheet appraisal_agency_file
A1: =HYPERLINK("#表结构清单!A1","返回") | B1: 评级机构附件
B2: 表名 | C2: 列名 | D2: 字段类型 | E2: 是否为空 | F2: 字段注释 | G2: 码值 | H2: 备注 | I2: 修订人 | J2: 修订日期
B3: appraisal_agency_file | C3: FILENO | D3: varchar(32) | E3: NO | F3: 文档编号 | J3: 2023/01/12
B4: appraisal_agency_file | C4: APPRAISALORGID | D4: varchar(32) | E4: NO | F4: 评估公司组织机构代码证 | J4: 2023/01/12
B5: appraisal_agency_file | C5: FILENAME | D5: varchar(80) | E5: YES | F5: 文档名称 | J5: 2023/01/12
B6: appraisal_agency_file | C6: INPUTUSERID | D6: varchar(32) | E6: YES | F6: 登记人 | J6: 2023/01/12
B7: appraisal_agency_file | C7: INPUTORGID | D7: varchar(32) | E7: YES | F7: 登记机构 | J7: 2023/01/12
B8: appraisal_agency_file | C8: INPUTDATE | D8: datetime | E8: YES | F8: 登记日期 | J8: 2023/01/12
B9: appraisal_agency_file | C9: UPDATEUSERID | D9: varchar(32) | E9: YES | F9: 更新人 | J9: 2023/01/12
B10: appraisal_agency_file | C10: UPDATEORGID | D10: varchar(32) | E10: YES | F10: 更新机构 | J10: 2023/01/12
B11: appraisal_agency_file | C11: UPDATEDATE | D11: datetime | E11: YES | F11: 更新日期 | J11: 2023/01/12
B12: appraisal_agency_file | C12: REMARK | D12: varchar(500) | E12: YES | F12: 备注 | J12: 2023/01/12
B13: appraisal_agency_file | C13: CORPORGID | D13: varchar(32) | E13: YES | F13: 法人机构编号 | J13: 2023/01/12

Sheet appraisal_agency_information
A1: =HYPERLINK("#表结构清单!A1","返回") | B1: 评估公司相关信息
B2: 表名 | C2: 列名 | D2: 字段类型 | E2: 是否为空 | F2: 字段注释 | G2: 码值 | H2: 备注 | I2: 修订人 | J2: 修订日期
B3: appraisal_agency_information | C3: SERIALNO | D3: varchar(32) | E3: NO | F3: 流水号 | J3: 2023/01/12
B4: appraisal_agency_information | C4: APPRAISALORGID | D4: varchar(32) | E4: NO | F4: 评估公司组织机构代码证 | J4: 2023/01/12
B5: appraisal_agency_information | C5: INFORMATIONTYPE | D5: varchar(18) | E5: YES | F5: 信息类型 | G5: =HYPERLINK("#码值映射清单!B10076","AgencyInformationType") | J5: 2023/01/12
B6: appraisal_agency_information | C6: ATTRIBUTE1 | D6: varchar(80) | E6: YES | F6: 联系人列表_姓名;资质情况_资质证书名称，专家信息_姓名，大事信息_标题 | J6: 2023/01/12
B7: appraisal_agency_information | C7: ATTRIBUTE2 | D7: varchar(32) | E7: YES | F7: 联系人列表_电话;资质情况_资质证书标号，专家信息_电话，大事信息_无 | J7: 2023/01/12
B8: appraisal_agency_information | C8: ATTRIBUTE3 | D8: varchar(32) | E8: YES | F8: 联系人列表_所属部门;资质情况_无，专家信息_所属部门，大事信息_无 | J8: 2023/01/12
B9: appraisal_agency_information | C9: ATTRIBUTE4 | D9: varchar(18) | E9: YES | F9: 联系人列表_是否有效;资质情况_执业资质等级，专家信息_无，大事信息_是否有效 | G9: =HYPERLINK("#码值映射清单!B5150","YesNo") | J9: 2023/01/12
B10: appraisal_agency_information | C10: ATTRIBUTE6 | D10: datetime | E10: YES | F10: 联系人列表_无;资质情况_资质核准日期，专家信息_无，大事信息_发生日期 | J10: 2023/01/12
B11: appraisal_agency_information | C11: ATTRIBUTE7 | D11: datetime | E11: YES | F11: 联系人列表_无;资质情况_资质到期日期，专家信息_无，大事信息_无 | J11: 2023/01/12
B12: appraisal_agency_information | C12: WORKYEARS | D12: varchar(6) | E12: YES | F12: 从业年限 | J12: 2023/01/12
B13: appraisal_agency_information | C13: INPUTUSERID | D13: varchar(32) | E13: YES | F13: 登记人 | J13: 2023/01/12
B14: appraisal_agency_information | C14: INPUTORGID | D14: varchar(32) | E14: YES | F14: 登记机构 | J14: 2023/01/12
B15: appraisal_agency_information | C15: INPUTDATE | D15: datetime | E15: YES | F15: 登记日期 | J15: 2023/01/12
B16: appraisal_agency_information | C16: UPDATEUSERID | D16: varchar(32) | E16: YES | F16: 更新人 | J16: 2023/01/12
B17: appraisal_agency_information | C17: UPDATEORGID | D17: varchar(32) | E17: YES | F17: 更新机构 | J17: 2023/01/12
B18: appraisal_agency_information | C18: UPDATEDATE | D18: datetime | E18: YES | F18: 更新日期 | J18: 2023/01/12
B19: appraisal_agency_information | C19: REMARK | D19: varchar(500) | E19: YES | F19: 备注 | J19: 2023/01/12
B20: appraisal_agency_information | C20: CORPORGID | D20: varchar(32) | E20: YES | F20: 法人机构编号 | J20: 2023/01/12
B21: appraisal_agency_information | C21: ATTRIBUTE5 | D21: varchar(1000) | E21: YES | F21: 联系人列表_无;资质情况_无，专家信息_专业领域，大事信息_事件描述及原因 | J21: 2023/01/12

Sheet appraisal_agency_qualification
A1: =HYPERLINK("#表结构清单!A1","返回") | B1: 评估机构资质表
B2: 表名 | C2: 列名 | D2: 字段类型 | E2: 是否为空 | F2: 字段注释 | G2: 码值 | H2: 备注 | I2: 修订人 | J2: 修订日期
B3: appraisal_agency_qualification | C3: EVENTSERIALNO | D3: varchar(32) | E3: NO | F3: 评估机构事件编号 | J3: 2023/01/12
B4: appraisal_agency_qualification | C4: EVENTTYPE | D4: varchar(32) | E4: YES | F4: 事件类型 | J4: 2023/01/12
B5: appraisal_agency_qualification | C5: ADMITTANCETYPE | D5: varchar(18) | E5: YES | F5: 准入评估类型 | J5: 2023/01/12
B6: appraisal_agency_qualification | C6: ISONCEACCESS | D6: char(1) | E6: YES | F6: 是否曾经准入 | J6: 2023/01/12
B7: appraisal_agency_qualification | C7: ISSPECIALACCESS | D7: char(1) | E7: YES | F7: 是否为特殊准入 | J7: 2023/01/12
B8: appraisal_agency_qualification | C8: COMPOSITESCOPE | D8: decimal(18,8) | E8: YES | F8: 评估机构综合得分 | J8: 2023/01/12
B9: appraisal_agency_qualification | C9: OCCURYEAR | D9: int | E9: YES | F9: 发生年度 | J9: 2023/01/12
B10: appraisal_agency_qualification | C10: OCCURREASON | D10: varchar(500) | E10: YES | F10: 发生原因 | J10: 2023/01/12
B11: appraisal_agency_qualification | C11: REMARK | D11: varchar(500) | E11: YES | F11: 备注 | J11: 2023/01/12
B12: appraisal_agency_qualification | C12: INPUTUSERID | D12: varchar(32) | E12: YES | F12: 登记人 | J12: 2023/01/12
B13: appraisal_agency_qualification | C13: INPUTORGID | D13: varchar(32) | E13: YES | F13: 登记机构 | J13: 2023/01/12
B14: appraisal_agency_qualification | C14: INPUTDATE | D14: datetime | E14: YES | F14: 登记日期 | J14: 2023/01/12
... B18: appraisal_agency_qualification | C18: CORPORGID | D18: varchar(32) | E18: YES | F18: 法人机构编号 | J18: 2023/01/12

Sheet appraisal_apply_relative
A1: =HYPERLINK("#表结构清单!A1","返回") | B1: 评级机构申请关联表
B2: 表名 | C2: 列名 | D2: 字段类型 | E2: 是否为空 | F2: 字段注释 | G2: 码值 | H2: 备注 | I2: 修订人 | J2: 修订日期
B3: appraisal_apply_relative | C3: EVENTSERIALNO | D3: varchar(32) | E3: NO | F3: 评估机构事件编号 | J3: 2023/01/12
B4: appraisal_apply_relative | C4: APPRAISALORGID | D4: varchar(32) | E4: YES | F4: 评估机构编号 | J4: 2023/01/12
B5: appraisal_apply_relative | C5: REMARK | D5: varchar(1000) | E5: YES | F5: 备注 | J5: 2023/01/12
B6: appraisal_apply_relative | C6: INPUTUSERID | D6: varchar(32) | E6: YES | F6: 登记人 | J6: 2023/01/12
B7: appraisal_apply_relative | C7: INPUTORGID | D7: varchar(32) | E7: YES | F7: 登记机构 | J7: 2023/01/12
B8: appraisal_apply_relative | C8: INPUTDATE | D8: datetime | E8: YES | F8: 登记日期 | J8: 2023/01/12
B9: appraisal_apply_relative | C9: UPDATEUSERID | D9: varchar(32) | E9: YES | F9: 更新人 | J9: 2023/01/12
B10: appraisal_apply_relative | C10: UPDATEORGID | D10: varchar(32) | E10: YES | F10: 更新机构 | J10: 2023/01/12
B11: appraisal_apply_relative | C11: UPDATEDATE | D11: datetime | E11: YES | F11: 更新日期 | J11: 2023/01/12

Sheet awe_bizfile_info
A1: =HYPERLINK("#表结构清单!A1","返回") | B1: 业务文件详情
B2: 表名 | C2: 列名 | D2: 字段类型 | E2: 是否为空 | F2: 字段注释 | G2: 码值 | H2: 备注 | I2: 修订人 | J2: 修订日期
B3: awe_bizfile_info | C3: FILENO | D3: varchar(32) | E3: NO | F3: 文件编号; | J3: 2023/01/12
B4: awe_bizfile_info | C4: FILEPATH | D4: varchar(500) | E4: YES | F4: 文件路径; | J4: 2023/01/12
B5: awe_bizfile_info | C5: FILEDESC | D5: varchar(500) | E5: YES | F5: 文件描述; | J5: 2023/01/12
B6: awe_bizfile_info | C6: CATALOGINFO | D6: varchar(500) | E6: YES | F6: 目录详情; | J6: 2023/01/12
B7: awe_bizfile_info | C7: ISTEMPORARY | D7: varchar(18) | E7: YES | F7: 是否临时; | J7: 2023/01/12
B8: awe_bizfile_info | C8: LATESTDOUSERID | D8: varchar(32) | E8: YES | F8: 最新下载用户; | J8: 2023/01/12
B9: awe_bizfile_info | C9: DOWNLOADCOUNT | D9: int | E9: YES | F9: 下载次数; | J9: 2023/01/12
B10: awe_bizfile_info | C10: CREATEUSER | D10: varchar(32) | E10: YES | F10: 创建人; | J10: 2023/01/12
B11: awe_bizfile_info | C11: CREATETIME | D11: varchar(32) | E11: YES | F11: 创建时间 | J11: 2023/01/12

Sheet awe_dict_errmsg
A1: =HYPERLINK("#表结构清单!A1","返回") | B1: 信息提示
B2: 表名 | C2: 列名 | D2: 字段类型 | E2: 是否为空 | F2: 字段注释 | G2: 码值 | H2: 备注 | I2: 修订人 | J2: 修订日期
B3: awe_dict_errmsg | C3: MSGNO | D3: varchar(32) | E3: NO | F3: 错误编号 | J3: 2023/01/12
B4: awe_dict_errmsg | C4: MSGTYPE | D4: varchar(18) | E4: YES | F4: 错误主题 | J4: 2023/01/12
B5: awe_dict_errmsg | C5: MSGTEXT | D5: varchar(500) | E5: YES | F5: 报告内容 | J5: 2023/01/12
B6: awe_dict_errmsg | C6: ENTEXT | D6: varchar(500) | E6: YES | F6: 图片地址 | J6: 2023/01/12
B7: awe_dict_errmsg | C7: INPUTORGID | D7: varchar(32) | E7: YES | F7: 登记机构 | J7: 2023/01/12
B8: awe_dict_errmsg | C8: INPUTUSERID | D8: varchar(32) | E8: YES | F8: 登记人 | J8: 2023/01/12
B9: awe_dict_errmsg | C9: INPUTDATE | D9: datetime | E9: YES | F9: 登记日期 | J9: 2023/01/12
B10: awe_dict_errmsg | C10: UPDATEORGID | D10: varchar(32) | E10: YES | F10: 更新机构 | J10: 2023/01/12
B11: awe_dict_errmsg | C11: UPDATEUSERID | D11: varchar(32) | E11: YES | F11: 更新人 | J11: 2023/01/12
B12: awe_dict_errmsg | C12: UPDATEDATE | D12: datetime | E12: YES | F12: 更新时间 | J12: 2023/01/12
